Workbook

Sheet USE OF DATA
C1: WHAT DO USERS WANT?
C2: MAIN USE OF DATA | D2: WHAT DATA SHOULD I USE? | E2: WORKSHEET
B3: 1 | C3: Policy Formulations | D3: The original unadjusted series and all components | E3: Original_VA
B4: 2 | C4: Macro-economic model building | D4: Could be Unadjusted, adjusted, trend-cycle or all components depending on the main purpose of the model | E4: Original_VA, Deseason_VA, Trend_VA
B5: 3 | C5: To determine what actually happened | D5: The original unadjusted series | E5: Original_VA
B6: 4 | C6: Analysis of the effect of particular events such as a strike | D6: The irregular component | E6: Deseason_VA and Trend_VA
B7: 5 | C7: Business Cycle analysis & detection of turning points | D7: Trend-cycle and irregular component | E7: Trend_VA
B8: 6 | C8: Short-term and medium term forecasting | D8: Original unadjusted series and all its components | E8: Original_VA
B9: 7 | C9: Long-term forecasting | D9: The trend cycle component | E9: Trend_VA
C12: Notes:
B13: a | C13: Original (Unadjusted) estimates have been benchmarked to the 2024/25 Annual GDP estimates (October release 2025) due to quarterly differences in source data for selected economic activities. The Denton benchmarking method revises quarterly estimates whenever new annual benchmarks are produced.
B14: b | C14: Therefore, there were no revisions in series because the benchmarks and input data have not been revised over the period. Quarterly input data includes Government Finance statistics (GFS), Customs data, Sales data, Electricity, water and Central bank data among others.
B15: c | C15: Seasonally adjusted data are subject to revisions as future data become available, even when the original data are not revised.
B16: d | C16: Seasonally adjusted and Trend-cycle estimates represent an analytical elaboration of the data designed to show the underlying movements that may be hidden by the seasonal variations.
B17: e | C17: Seasonally adjusted data is the sum of the Trend-cycle component and the Irregular component. When the Irregular component is strong, the Seasonally adjusted series may not present a smooth pattern.
B18: f | C18: Original (Unadjusted) data are useful in their own right. They show the actual economic events that have occurred and therefore Seasonally adjusted data should not replace the unadjusted data.
B19: h | C19: In terms of interpretation, original series consider year on year similar quarter changes due to seasonal effects while adjusted series consider quarter to quarter changes.

Sheet Summary
A2: TABLE 1: SUMMARY OF QGDP AT CONSTANT 2016/17 PRICES, BILLION SHILLINGS, 2016/17-2025/26
A3: Year | B3: 2016/17 | F3: 2017/18 | G3: 2017/18 | J3: 2018/19 | N3: 2019/20 | R3: 2020/21 | V3: 2021/22 | Z3: 2022/23 | AD3: 2023/24 | AH3: 2024/25 | AL3: 2025/26
A4: Period | B4: Q1 | C4: Q2 | D4: Q3 | E4: Q4 | F4: Q1 | G4: Q2 | H4: Q3 | I4: Q4 | J4: Q1 | K4: Q2 | L4: Q3 | M4: Q4 | N4: Q1 | O4: Q2 | P4: Q3 | Q4: Q4 | R4: Q1 | S4: Q2 | T4: Q3 | U4: Q4 | V4: Q1 | W4: Q2 | X4: Q3 | Y4: Q4 | Z4: Q1 | AA4: Q2 | AB4: Q3 | AC4: Q4 | AD4: Q1 | AE4: Q2 | AF4: Q3 | AG4: Q4 | AH4: Q1 | AI4: Q2 | AJ4: Q3 | AK4: Q4 | AL4: Q1 | AM4: Q2
A5: ORIGINAL ESTIMATES
A6: GDP at market prices | B6: 28577.247 | C6: 26610.18 | D6: 26240.178 | E6: 27090.435 | F6: 30772.237 | G6: 28335.28 | H6: 27653.331 | I6: 28598.087 | J6: 32487.642 | K6: 29958.631 | L6: 29773.235 | M6: 30567.095 | N6: 34943.779 | O6: 32466.458 | P6: 30130.072 | Q6: 28870.102 | R6: 34802.923 | S6: 32477.008 | T6: 30975.024 | U6: 32626.063 | V6: 35622.436 | W6: 34024.49 | X6: 32716.662 | Y6: 34522.28 | Z6: 38746.737 | AA6: 35492.013 | AB6: 33446.228 | AC6: 36506.452 | AD6: 41068.072 | AE6: 37544.31 | AF6: 35728.791 | AG6: 38581.884 | AH6: 43605.836 | AI6: 39557.991 | AJ6: 38727.987 | AK6: 40714.044 | AL6: 45718.884 | AM6: 42903.876
A7: Agriculture, Forestry & Fishing | B7: 8012.3898 | C7: 6110.5575 | D7: 5359.3298 | E7: 5974.7915 | F7: 8783.7536 | G7: 6199.5724 | H7: 5495.0897 | I7: 6096.0101 | J7: 8974.6097 | K7: 6448.4413 | L7: 5935.2774 | M7: 6628.7289 | N7: 9517.4185 | O7: 6941.2508 | P7: 5858.4835 | Q7: 7019.6669 | R7: 10178.838 | S7: 7480.0514 | T7: 5874.7257 | U7: 7070.5839 | V7: 10624.95 | W7: 7330.892 | X7: 6120.4467 | Y7: 7804.9868 | Z7: 11088.263 | AA7: 8197.4364 | AB7: 6452.1008 | AC7: 7589.8403 | AD7: 11715.27 | AE7: 8365.8311 | AF7: 6712.9791 | AG7: 8392.5624 | AH7: 12457.04 | AI7: 9018.0558 | AJ7: 7404.8569 | AK7: 8683.3829 | AL7: 12839.64 | AM7: 9809.0589
A8: Industry | B8: 6768.7131 | C8: 7106.8656 | D8: 7305.421 | E8: 7067.3259 | F8: 7134.9059 | G8: 7312.6318 | H8: 7537.2021 | I8: 7631.5343 | J8: 7779.6918 | K8: 8068.1838 | L8: 8243.5123 | M8: 8201.8824 | N8: 8570.2406 | O8: 8886.3356 | P8: 8486.7958 | Q8: 7398.8511 | R8: 8381.1058 | S8: 8755.7883 | T8: 8669.0779 | U8: 8693.4802 | V8: 8370.9467 | W8: 9440.8925 | X8: 9148.3498 | Y8: 9308.0376 | Z8: 9399.6503 | AA8: 9216.6242 | AB8: 9213.4013 | AC8: 9899.9765 | AD8: 10329.779 | AE8: 9629.9206 | AF8: 9832.8272 | AG8: 10008.679 | AH8: 10858.986 | AI8: 10366.745 | AJ8: 10560.436 | AK8: 10766.195 | AL8: 11507.782 | AM8: 11637.499
A9: Services | B9: 11937.718 | C9: 11574.904 | D9: 11626.766 | E9: 12042.627 | F9: 12862.303 | G9: 12815.187 | H9: 12685.299 | I9: 12837.368 | J9: 13754.229 | K9: 13368.754 | L9: 13465.069 | M9: 13600.746 | N9: 14658.784 | O9: 14367.919 | P9: 13669.805 | Q9: 12849.732 | R9: 14119.436 | S9: 14074.464 | T9: 14391.411 | U9: 14495.401 | V9: 14539.216 | W9: 14902.836 | X9: 14962.971 | Y9: 14980.554 | Z9: 15799.82 | AA9: 15607.29 | AB9: 15193.7 | AC9: 16317.733 | AD9: 16221.882 | AE9: 16906.179 | AF9: 16418.929 | AG9: 17379.216 | AH9: 17192.953 | AI9: 17283.665 | AJ9: 17847.735 | AK9: 18239.581 | AL9: 18170.905 | AM9: 18361.432
A10: Adjustments
A11: Taxes on products | B11: 1858.4261 | C11: 1817.8528 | D11: 1948.6611 | E11: 2005.691 | F11: 1991.2744 | G11: 2007.8887 | H11: 1935.7403 | I11: 2033.1747 | J11: 1979.1119 | K11: 2073.2514 | L11: 2129.377 | M11: 2135.7379 | N11: 2197.3365 | O11: 2270.9524 | P11: 2114.9878 | Q11: 1601.8521 | R11: 2123.5437 | S11: 2166.7043 | T11: 2039.8093 | U11: 2366.598 | V11: 2087.3237 | W11: 2349.8691 | X11: 2484.895 | Y11: 2428.7012 | Z11: 2459.0041 | AA11: 2470.6617 | AB11: 2587.0261 | AC11: 2698.9015 | AD11: 2801.1416 | AE11: 2642.3794 | AF11: 2764.0558 | AG11: 2801.4262 | AH11: 3096.8575 | AI11: 2889.5255 | AJ11: 2914.9594 | AK11: 3024.8849 | AL11: 3200.5564 | AM11: 3095.8858
A13: SEASONALLY ADJUSTED ESTIMATES
A14: GDP at market prices | B14: 26418.33 | C14: 26820.341 | D14: 27619.794 | E14: 27877.519 | F14: 28291.339 | G14: 28562.977 | H14: 29225.636 | I14: 29425.25 | J14: 29958.925 | K14: 30153.094 | L14: 31561.031 | M14: 31371.83 | N14: 32311.887 | O14: 32681.047 | P14: 31941.991 | Q14: 29638.437 | R14: 31936.886 | S14: 32665.96 | T14: 32913.148 | U14: 33266.263 | V14: 32690.007 | W14: 34248.282 | X14: 35004.411 | Y14: 35114.23 | Z14: 35517.737 | AA14: 35836.545 | AB14: 35798.781 | AC14: 36969.932 | AD14: 37483.15 | AE14: 38034.023 | AF14: 38330.506 | AG14: 38995.258 | AH14: 39825.16 | AI14: 40146.528 | AJ14: 41458.228 | AK14: 41147.854 | AL14: 41936.505 | AM14: 43598.4
A15: Agriculture, Forestry & Fishing | B15: 6113.5807 | C15: 6365.3902 | D15: 6582.613 | E15: 6545.5468 | F15: 6624.4085 | G15: 6533.6463 | H15: 6886.5598 | I15: 6658.9337 | J15: 6779.4574 | K15: 6777.7826 | L15: 7530.1008 | M15: 7187.1377 | N15: 7185.5965 | O15: 7287.0483 | P15: 7449.7978 | Q15: 7591.413 | R15: 7576.6284 | S15: 7813.6823 | T15: 7522.4789 | U15: 7637.3368 | V15: 7927.1369 | W15: 7630.167 | X15: 8035.5081 | Y15: 8447.1775 | Z15: 8159.0795 | AA15: 8513.0207 | AB15: 8383.2101 | AC15: 8246.0464 | AD15: 8605.2413 | AE15: 8671.4432 | AF15: 8843.9697 | AG15: 9113.9734 | AH15: 9189.0095 | AI15: 9308.9636 | AJ15: 9634.1005 | AK15: 9429.3307 | AL15: 9593.9998 | AM15: 10108.554
A16: Industry | B16: 6810.6034 | C16: 7063.7601 | D16: 7254.0027 | E16: 7141.0369 | F16: 7166.4739 | G16: 7225.7595 | H16: 7502.9433 | I16: 7726.2775 | J16: 7801.3782 | K16: 7960.7061 | L16: 8233.1105 | M16: 8293.8714 | N16: 8575.638 | O16: 8793.2643 | P16: 8516.0149 | Q16: 7475.9913 | R16: 8344.0458 | S16: 8664.3391 | T16: 8746.7761 | U16: 8744.402 | V16: 8320.4574 | W16: 9400.4202 | X16: 9287.252 | Y16: 9327.8918 | Z16: 9270.1095 | AA16: 9216.431 | AB16: 9362.2701 | AC16: 9903.2747 | AD16: 10051.235 | AE16: 9693.1081 | AF16: 10001.426 | AG16: 9991.0365 | AH16: 10553.501 | AI16: 10470.413 | AJ16: 10737.855 | AK16: 10743.283 | AL16: 11200.126 | AM16: 11777.905
A17: Services | B17: 11610.862 | C17: 11586.137 | D17: 11813.858 | E17: 12212.573 | F17: 12489.013 | G17: 12814.711 | H17: 12875.605 | I17: 13027.644 | J17: 13383.12 | K17: 13363.712 | L17: 13643.786 | M17: 13769.895 | N17: 14342.035 | O17: 14348.651 | P17: 13842.032 | Q17: 12976.614 | R17: 13891.505 | S17: 14030.582 | T17: 14588.772 | U17: 14518.594 | V17: 14373.181 | W17: 14859.667 | X17: 15183.909 | Y17: 14904.481 | Z17: 15673.293 | AA17: 15606.616 | AB17: 15455.052 | AC17: 16110.687 | AD17: 16092.728 | AE17: 16979.164 | AF17: 16709.108 | AG17: 17074.679 | AH17: 17070.877 | AI17: 17417.405 | AJ17: 18157.649 | AK17: 17935.607 | AL17: 18035.152 | AM17: 18549.363
A18: Adjustments
A19: Taxes on products | B19: 1883.2834 | C19: 1805.0535 | D19: 1969.3194 | E19: 1978.3628 | F19: 2011.4434 | G19: 1988.86 | H19: 1960.5283 | I19: 2012.3942 | J19: 1994.9695 | K19: 2050.8934 | L19: 2154.0345 | M19: 2120.9253 | N19: 2208.6176 | O19: 2252.0829 | P19: 2134.1464 | Q19: 1594.4186 | R19: 2124.7071 | S19: 2157.3562 | T19: 2055.1209 | U19: 2365.9306 | V19: 2069.2315 | W19: 2358.027 | X19: 2497.7416 | Y19: 2434.6792 | Z19: 2415.2547 | AA19: 2500.4775 | AB19: 2598.2494 | AC19: 2709.924 | AD19: 2733.946 | AE19: 2690.3075 | AF19: 2776.001 | AG19: 2815.5688 | AH19: 3011.7728 | AI19: 2949.7457 | AJ19: 2928.624 | AK19: 3039.6326 | AL19: 3107.2263 | AM19: 3162.5776
A21: TREND CYCLE ESTIMATES
A22: GDP at market prices | B22: 26462.729 | C22: 26896.395 | D22: 27382.403 | E22: 27823.292 | F22: 28161.943 | G22: 28513.962 | H22: 28957.26 | I22: 29462.114 | J22: 29881.613 | K22: 30348.906 | L22: 30850.88 | M22: 31471.349 | N22: 32206.382 | O22: 32534.765 | P22: 32175.212 | Q22: 32026.06 | R22: 32219.26 | S22: 32509.801 | T22: 32839.663 | U22: 32898.971 | V22: 33160.329 | W22: 34069.828 | X22: 34839.343 | Y22: 35033.552 | Z22: 35348.49 | AA22: 35585.28 | AB22: 36078.587 | AC22: 36779.913 | AD22: 37191.742 | AE22: 37418.391 | AF22: 38268.834 | AG22: 39291.159 | AH22: 39872.71 | AI22: 40241.212 | AJ22: 40656.363 | AK22: 41347.988 | AL22: 42239.942 | AM22: 43273.383
A23: Agriculture, Forestry & Fishing | B23: 6219.3427 | C23: 6294.9669 | D23: 6407.4385 | E23: 6477.3375 | F23: 6492.3673 | G23: 6510.6472 | H23: 6592.6195 | I23: 6679.9926 | J23: 6762.4404 | K23: 6851.8703 | L23: 6974.0034 | M23: 7093.5297 | N23: 7177.9759 | O23: 7247.1952 | P23: 7351.7641 | Q23: 7498.5506 | R23: 7601.7848 | S23: 7595.9446 | T23: 7545.8478 | U23: 7498.9166 | V23: 7553.2979 | W23: 7784.6192 | X23: 8052.5733 | Y23: 8303.0837 | Z23: 8440.4735 | AA23: 8395.4301 | AB23: 8324.0587 | AC23: 8334.4393 | AD23: 8415.4908 | AE23: 8575.3602 | AF23: 8756.8475 | AG23: 8934.4361 | AH23: 9086.7845 | AI23: 9205.3115 | AJ23: 9283.9208 | AK23: 9390.2858 | AL23: 9596.0021 | AM23: 9897.4766
A24: Industry | B24: 6791.0364 | C24: 7077.731 | D24: 7200.174 | E24: 7178.8762 | F24: 7145.538 | G24: 7259.2795 | H24: 7489.921 | I24: 7702.2802 | J24: 7816.3296 | K24: 7986.6672 | L24: 8177.1601 | M24: 8347.9343 | N24: 8583.36 | O24: 8719.0967 | P24: 8659.4439 | Q24: 8631.8724 | R24: 8675.9397 | S24: 8693.6963 | T24: 8724.2683 | U24: 8713.2737 | V24: 8889.5175 | W24: 9198.4026 | X24: 9353.5156 | Y24: 9306.4883 | Z24: 9263.289 | AA24: 9216.4138 | AB24: 9447.5444 | AC24: 9800.8344 | AD24: 9860.4728 | AE24: 9788.7521 | AF24: 9945.4833 | AG24: 10259.871 | AH24: 10474.648 | AI24: 10592.303 | AJ24: 10632.774 | AK24: 10784.478 | AL24: 11190.244 | AM24: 11740.477
A25: Services | B25: 11589.542 | C25: 11612.456 | D25: 11823.783 | E25: 12175.714 | F25: 12522.111 | G25: 12757.821 | H25: 12896.904 | I25: 13088.897 | J25: 13295.481 | K25: 13447.922 | L25: 13578.028 | M25: 13877.968 | N25: 14239.943 | O25: 14349.331 | P25: 13984.686 | Q25: 13745.471 | R25: 13790.337 | S25: 14083.848 | T25: 14424.047 | U25: 14513.376 | V25: 14468.768 | W25: 14713.635 | X25: 14970.425 | Y25: 14975.687 | Z25: 15218.231 | AA25: 15479.82 | AB25: 15701.178 | AC25: 15943.64 | AD25: 16194.829 | AE25: 16336.623 | AF25: 16815.867 | AG25: 17245.556 | AH25: 17370.262 | AI25: 17488.209 | AJ25: 17789.05 | AK25: 18148.771 | AL25: 18347.572 | AM25: 18470.604
A26: Adjustments
A27: Taxes on products | B27: 1862.8078 | C27: 1911.2419 | D27: 1951.0075 | E27: 1991.364 | F27: 2001.9261 | G27: 1986.2144 | H27: 1977.8154 | I27: 1990.9443 | J27: 2007.3618 | K27: 2062.4461 | L27: 2121.6887 | M27: 2151.9172 | N27: 2205.1039 | O27: 2219.1416 | P27: 2179.3171 | Q27: 2150.1665 | R27: 2151.1983 | S27: 2136.3114 | T27: 2145.5 | U27: 2173.405 | V27: 2248.7455 | W27: 2373.1712 | X27: 2462.8291 | Y27: 2448.2929 | Z27: 2426.4969 | AA27: 2493.6157 | AB27: 2605.8057 | AC27: 2700.9992 | AD27: 2720.9495 | AE27: 2717.6552 | AF27: 2750.6356 | AG27: 2851.2955 | AH27: 2941.015 | AI27: 2955.3882 | AJ27: 2950.618 | AK27: 3024.4541 | AL27: 3106.1235 | AM27: 3164.8249
A29: Source: Uganda Bureau of Statistics
A31: TABLE 2: SUMMARY OF QGDP AT CONSTANT 2016/17 PRICES, PERCENTAGE CHANGE, 2016/17-2025/26
A32: Year | B32: 2016/17 | F32: 2017/18 | G32: 2017/18 | J32: 2018/19 | N32: 2019/20 | R32: 2020/21 | V32: 2021/22 | Z32: 2022/23 | AD32: 2023/24 | AH32: 2024/25 | AL32: 2025/26
A33: Period | B33: Q1 | C33: Q2 | D33: Q3 | E33: Q4 | F33: Q1 | G33: Q2 | H33: Q3 | I33: Q4 | J33: Q1 | K33: Q2 | L33: Q3 | M33: Q4 | N33: Q1 | O33: Q2 | P33: Q3 | Q33: Q4 | R33: Q1 | S33: Q2 | T33: Q3 | U33: Q4 | V33: Q1 | W33: Q2 | X33: Q3 | Y33: Q4 | Z33: Q1 | AA33: Q2 | AB33: Q3 | AC33: Q4 | AD33: Q1 | AE33: Q2 | AF33: Q3 | AG33: Q4 | AH33: Q1 | AI33: Q2 | AJ33: Q3 | AK33: Q4 | AL33: Q1 | AM33: Q2
A34: ORIGINAL ESTIMATES
A35: GDP at market prices | B35: -0.26122599 | C35: 0.50756396 | D35: 6.7464548 | E35: 6.1811727 | F35: 7.6808998 | G35: 6.4828574 | H35: 5.3854549 | I35: 5.5652552 | J35: 5.5745218 | K35: 5.7290794 | L35: 7.6659989 | M35: 6.8851035 | N35: 7.5602194 | O35: 8.3709675 | P35: 1.1985158 | Q35: -5.5516965 | R35: -0.40309239 | S35: 0.032495737 | T35: 2.804345 | U35: 13.009861 | V35: 2.354724 | W35: 4.7648514 | X35: 5.6227189 | Y35: 5.811971 | Z35: 8.7705981 | AA35: 4.3131379 | AB35: 2.2299523 | AC35: 5.7475112 | AD35: 5.9910476 | AE35: 5.7824205 | AF35: 6.8245768 | AG35: 5.6851104 | AH35: 6.1794064 | AI35: 5.3634777 | AJ35: 8.394339 | AK35: 5.5263248 | AL35: 4.8457919 | AM35: 8.4581777
A36: Agriculture, Forestry & Fishing | B36: 1.1733408 | C36: 3.2296506 | D36: 1.0636812 | E36: 6.0861995 | F36: 9.6271373 | G36: 1.4567401 | H36: 2.5331515 | I36: 2.0288347 | J36: 2.172831 | K36: 4.0142917 | L36: 8.010565 | M36: 8.7388102 | N36: 6.0482714 | O36: 7.6423041 | P36: -1.2938559 | Q36: 5.8976315 | R36: 6.9495696 | S36: 7.7622984 | T36: 0.27724211 | U36: 0.72534795 | V36: 4.382736 | W36: -1.9940967 | X36: 4.1826802 | Y36: 10.386736 | Z36: 4.3606145 | AA36: 11.82045 | AB36: 5.4187897 | AC36: -2.7565253 | AD36: 5.654692 | AE36: 2.0542364 | AF36: 4.0433085 | AG36: 10.57627 | AH36: 6.331648 | AI36: 7.796292 | AJ36: 10.306569 | AK36: 3.4652179 | AL36: 3.0713611 | AM36: 8.7713266
A37: Industry | B37: -0.60233732 | C37: 4.5995317 | D37: 16.225662 | E37: 7.9277803 | F37: 5.4100804 | G37: 2.8953153 | H37: 3.1727275 | I37: 7.983336 | J37: 9.0370626 | K37: 10.33215 | L37: 9.3709856 | M37: 7.4735698 | N37: 10.161699 | O37: 10.14047 | P37: 2.9512124 | Q37: -9.7908167 | R37: -2.2068791 | S37: -1.4690787 | T37: 2.1478318 | U37: 17.497705 | V37: -0.121214 | W37: 7.8245859 | X37: 5.5285218 | Y37: 7.0691761 | Z37: 12.288976 | AA37: -2.3754988 | AB37: 0.71107424 | AC37: 6.3594382 | AD37: 9.8953589 | AE37: 4.4842493 | AF37: 6.7230965 | AG37: 1.0980079 | AH37: 5.1231152 | AI37: 7.6514026 | AJ37: 7.3997957 | AK37: 7.5685941 | AL37: 5.9747366 | AM37: 12.257991
A38: Services | B38: -2.4907341 | C38: -3.736009 | D38: 2.5175007 | E38: 4.5088343 | F38: 7.7450719 | G38: 10.715277 | H38: 9.1042744 | I38: 6.5993997 | J38: 6.9344151 | K38: 4.3196164 | L38: 6.1470326 | M38: 5.9465301 | N38: 6.576558 | O38: 7.4738828 | P38: 1.5205013 | Q38: -5.5218535 | R38: -3.6793477 | S38: -2.042432 | T38: 5.2788271 | U38: 12.807022 | V38: 2.9730667 | W38: 5.8856353 | X38: 3.9715352 | Y38: 3.3469497 | Z38: 8.6703688 | AA38: 4.7269825 | AB38: 1.5420013 | AC38: 8.9260995 | AD38: 2.6713069 | AE38: 8.3223194 | AF38: 8.0640636 | AG38: 6.505087 | AH38: 5.9861799 | AI38: 2.2328288 | AJ38: 8.7021833 | AK38: 4.9505378 | AL38: 5.6881024 | AM38: 6.2357551
A39: Adjustments
A40: Taxes on products | B40: 10.604422 | C40: 4.5985732 | D40: 17.953651 | E40: 10.804192 | F40: 7.14843 | G40: 10.453864 | H40: -0.66306097 | I40: 1.3702884 | J40: -0.61078727 | K40: 3.2552983 | L40: 10.00324 | M40: 5.0444829 | N40: 11.026391 | O40: 9.535794 | P40: -0.67574802 | Q40: -24.997721 | R40: -3.3582876 | S40: -4.5905031 | T40: -3.5545582 | U40: 47.741356 | V40: -1.7056382 | W40: 8.453615 | X40: 21.819967 | Y40: 2.6241571 | Z40: 17.806552 | AA40: 5.1403958 | AB40: 4.1100754 | AC40: 11.125298 | AD40: 13.913662 | AE40: 6.9502737 | AF40: 6.8429801 | AG40: 3.7987589 | AH40: 10.556979 | AI40: 9.3531628 | AJ40: 5.4594994 | AK40: 7.9766044 | AL40: 3.3485178 | AM40: 7.1416697
A42: SEASONALLY ADJUSTED ESTIMATES
A43: GDP at market prices | B43: 0.86546068 | C43: 1.5217117 | D43: 2.9807704 | E43: 0.93312038 | F43: 1.4844207 | G43: 0.96014433 | H43: 2.3199933 | I43: 0.68300934 | J43: 1.8136644 | K43: 0.64811638 | L43: 4.6692978 | M43: -0.5994792 | N43: 2.996502 | O43: 1.1424887 | P43: -2.2614196 | Q43: -7.2116804 | R43: 7.7549618 | S43: 2.2828561 | T43: 0.75671459 | U43: 1.0728699 | V43: -1.7322538 | W43: 4.766823 | X43: 2.2077868 | Y43: 0.31372912 | Z43: 1.149128 | AA43: 0.89760246 | AB43: -0.10537823 | AC43: 3.2714827 | AD43: 1.3882041 | AE43: 1.4696532 | AF43: 0.77952016 | AG43: 1.7342644 | AH43: 2.1282137 | AI43: 0.80694549 | AJ43: 3.2672815 | AK43: -0.74864265 | AL43: 1.9166271 | AM43: 3.9628848
A44: Agriculture, Forestry & Fishing | B44: -0.95264124 | C44: 4.1188552 | D44: 3.4125598 | E44: -0.56309295 | F44: 1.2048157 | G44: -1.3701187 | H44: 5.4014788 | I44: -3.3053667 | J44: 1.809954 | K44: -0.024703168 | L44: 11.099768 | M44: -4.554562 | N44: -0.02144354 | O44: 1.4118782 | P44: 2.2334067 | Q44: 1.9009271 | R44: -0.19475384 | S44: 3.1287517 | T44: -3.7268402 | U44: 1.5268624 | V44: 3.7945184 | W44: -3.7462449 | X44: 5.3123497 | Y44: 5.1231289 | Z44: -3.4105828 | AA44: 4.3380037 | AB44: -1.5248479 | AC44: -1.6361716 | AD44: 4.3559656 | AE44: 0.76931957 | AF44: 1.9895942 | AG44: 3.0529694 | AH44: 0.82330881 | AI44: 1.3054081 | AJ44: 3.492729 | AK44: -2.1254685 | AL44: 1.7463496 | AM44: 5.3632931
A45: Industry | B45: 3.1670471 | C45: 3.717097 | D45: 2.6932197 | E45: -1.5572898 | F45: 0.35620939 | G45: 0.82726373 | H45: 3.8360498 | I45: 2.9766219 | J45: 0.97201608 | K45: 2.042305 | L45: 3.4218618 | M45: 0.73800683 | N45: 3.3972867 | O45: 2.5377276 | P45: -3.1529752 | Q45: -12.212562 | R45: 11.61123 | S45: 3.8385845 | T45: 0.95145188 | U45: -0.027142845 | V45: -4.8481825 | W45: 12.979608 | X45: -1.2038631 | Y45: 0.43758695 | Z45: -0.61945777 | AA45: -0.57904912 | AB45: 1.582382 | AC45: 5.778562 | AD45: 1.4940567 | AE45: -3.5630162 | AF45: 3.1808 | AG45: -0.10388497 | AH45: 5.6296866 | AI45: -0.78729527 | AJ45: 2.5542563 | AK45: 0.050557372 | AL45: 4.2523591 | AM45: 5.15868
A46: Services | B46: -0.23506787 | C46: -0.21295183 | D46: 1.9654659 | E46: 3.3749736 | F46: 2.2635705 | G46: 2.6078739 | H46: 0.47518546 | I46: 1.1808353 | J46: 2.7286258 | K46: -0.14502166 | L46: 2.0957819 | M46: 0.92429978 | N46: 4.1550047 | O46: 0.046131214 | P46: -3.5307782 | Q46: -6.2521035 | R46: 7.0503066 | S46: 1.0011646 | T46: 3.9783803 | U46: -0.48104309 | V46: -1.0015607 | W46: 3.3846817 | X46: 2.1820235 | Y46: -1.8402888 | Z46: 5.1582627 | AA46: -0.42542075 | AB46: -0.97115419 | AC46: 4.2422081 | AD46: -0.11147455 | AE46: 5.5083025 | AF46: -1.5905116 | AG46: 2.1878533 | AH46: -0.022265295 | AI46: 2.0299339 | AJ46: 4.250023 | AK46: -1.2228544 | AL46: 0.55501444 | AM46: 2.8511598
...

Sheet Summary IPD
X2: Table 3: Summary of QGDP at constant 2009/10 prices, IMPLICIT PRICE DEFLATORS, 2013/14-2017/18
B3: 2007/08 | D3: 2008/09 | H3: 2009/10 | L3: 2010/11 | P3: 2011/12 | U3: 2012/13 | X3: 2013/14 | AB3: 2014/15 | AF3: 2015/16 | AJ3: 2016/17 | AN3: 2017/18
A4: ACTIVITY | B4: Q3 | C4: Q4 | D4: Q1 | E4: Q2 | F4: Q3 | G4: Q4 | H4: Q1 | I4: Q2 | J4: Q3 | K4: Q4 | L4: Q1 | M4: Q2 | N4: Q3 | O4: Q4 | P4: Q1 | Q4: Q2 | R4: Q3 | S4: Q4 | T4: Q1 | U4: Q2 | V4: Q3 | W4: Q4 | X4: Q1 | Y4: Q2 | Z4: Q3 | AA4: Q4 | AB4: Q1 | AC4: Q2 | AD4: Q3 | AE4: Q4 | AF4: Q1 | AG4: Q2 | AH4: Q3 | AI4: Q4 | AJ4: Q1 | AK4: Q2 | AL4: Q3 | AM4: Q4 | AN4: Q1 | AO4: Q2 | AP4: Q3 | AQ4: Q4
A5: ORIGINAL ESTIMATES
A6: GDP at market prices | B6: =#REF!/Summary!#REF!*100 -> #REF! | C6: =#REF!/Summary!#REF!*100 -> #REF! | D6: =#REF!/Summary!#REF!*100 -> #REF! | E6: =#REF!/Summary!#REF!*100 -> #REF! | F6: =#REF!/Summary!#REF!*100 -> #REF! | G6: =#REF!/Summary!#REF!*100 -> #REF! | H6: =#REF!/Summary!#REF!*100 -> #REF! | I6: =#REF!/Summary!#REF!*100 -> #REF! | ... AI6: =#REF!/Summary!#REF!*100 -> #REF! | AJ6: =#REF!/Summary!B6*100 -> #REF! | AK6: =#REF!/Summary!C6*100 -> #REF! | AL6: =#REF!/Summary!D6*100 -> #REF! | AM6: =#REF!/Summary!E6*100 -> #REF! | AN6: =#REF!/Summary!F6*100 -> #REF! | AO6: =#REF!/Summary!G6*100 -> #REF! | AP6: =#REF!/Summary!H6*100 -> #REF! | AQ6: =#REF!/Summary!I6*100 -> #REF!
A7: Agriculture, Forestry & Fishing | B7: =#REF!/Summary!#REF!*100 -> #REF! | C7: =#REF!/Summary!#REF!*100 -> #REF! | D7: =#REF!/Summary!#REF!*100 -> #REF! | E7: =#REF!/Summary!#REF!*100 -> #REF! | F7: =#REF!/Summary!#REF!*100 -> #REF! | G7: =#REF!/Summary!#REF!*100 -> #REF! | H7: =#REF!/Summary!#REF!*100 -> #REF! | I7: =#REF!/Summary!#REF!*100 -> #REF! | ... AI7: =#REF!/Summary!#REF!*100 -> #REF! | AJ7: =#REF!/Summary!B7*100 -> #REF! | AK7: =#REF!/Summary!C7*100 -> #REF! | AL7: =#REF!/Summary!D7*100 -> #REF! | AM7: =#REF!/Summary!E7*100 -> #REF! | AN7: =#REF!/Summary!F7*100 -> #REF! | AO7: =#REF!/Summary!G7*100 -> #REF! | AP7: =#REF!/Summary!H7*100 -> #REF! | AQ7: =#REF!/Summary!I7*100 -> #REF!
A8: Industry | B8: =#REF!/Summary!#REF!*100 -> #REF! | C8: =#REF!/Summary!#REF!*100 -> #REF! | D8: =#REF!/Summary!#REF!*100 -> #REF! | E8: =#REF!/Summary!#REF!*100 -> #REF! | F8: =#REF!/Summary!#REF!*100 -> #REF! | G8: =#REF!/Summary!#REF!*100 -> #REF! | H8: =#REF!/Summary!#REF!*100 -> #REF! | I8: =#REF!/Summary!#REF!*100 -> #REF! | ... AI8: =#REF!/Summary!#REF!*100 -> #REF! | AJ8: =#REF!/Summary!B8*100 -> #REF! | AK8: =#REF!/Summary!C8*100 -> #REF! | AL8: =#REF!/Summary!D8*100 -> #REF! | AM8: =#REF!/Summary!E8*100 -> #REF! | AN8: =#REF!/Summary!F8*100 -> #REF! | AO8: =#REF!/Summary!G8*100 -> #REF! | AP8: =#REF!/Summary!H8*100 -> #REF! | AQ8: =#REF!/Summary!I8*100 -> #REF!
A9: Services | B9: =#REF!/Summary!#REF!*100 -> #REF! | C9: =#REF!/Summary!#REF!*100 -> #REF! | D9: =#REF!/Summary!#REF!*100 -> #REF! | E9: =#REF!/Summary!#REF!*100 -> #REF! | F9: =#REF!/Summary!#REF!*100 -> #REF! | G9: =#REF!/Summary!#REF!*100 -> #REF! | H9: =#REF!/Summary!#REF!*100 -> #REF! | I9: =#REF!/Summary!#REF!*100 -> #REF! | ... AI9: =#REF!/Summary!#REF!*100 -> #REF! | AJ9: =#REF!/Summary!B9*100 -> #REF! | AK9: =#REF!/Summary!C9*100 -> #REF! | AL9: =#REF!/Summary!D9*100 -> #REF! | AM9: =#REF!/Summary!E9*100 -> #REF! | AN9: =#REF!/Summary!F9*100 -> #REF! | AO9: =#REF!/Summary!G9*100 -> #REF! | AP9: =#REF!/Summary!H9*100 -> #REF! | AQ9: =#REF!/Summary!I9*100 -> #REF!
A10: Adjustments
A11: Taxes on products | B11: =#REF!/Summary!#REF!*100 -> #REF! | C11: =#REF!/Summary!#REF!*100 -> #REF! | D11: =#REF!/Summary!#REF!*100 -> #REF! | E11: =#REF!/Summary!#REF!*100 -> #REF! | F11: =#REF!/Summary!#REF!*100 -> #REF! | G11: =#REF!/Summary!#REF!*100 -> #REF! | H11: =#REF!/Summary!#REF!*100 -> #REF! | I11: =#REF!/Summary!#REF!*100 -> #REF! | ... AI11: =#REF!/Summary!#REF!*100 -> #REF! | AJ11: =#REF!/Summary!B11*100 -> #REF! | AK11: =#REF!/Summary!C11*100 -> #REF! | AL11: =#REF!/Summary!D11*100 -> #REF! | AM11: =#REF!/Summary!E11*100 -> #REF! | AN11: =#REF!/Summary!F11*100 -> #REF! | AO11: =#REF!/Summary!G11*100 -> #REF! | AP11: =#REF!/Summary!H11*100 -> #REF! | AQ11: =#REF!/Summary!I11*100 -> #REF!
A13: SEASONALLY ADJUSTED ESTIMATES
A14: GDP at market prices | B14: =#REF!/Summary!#REF!*100 -> #REF! | C14: =#REF!/Summary!#REF!*100 -> #REF! | D14: =#REF!/Summary!#REF!*100 -> #REF! | E14: =#REF!/Summary!#REF!*100 -> #REF! | F14: =#REF!/Summary!#REF!*100 -> #REF! | G14: =#REF!/Summary!#REF!*100 -> #REF! | H14: =#REF!/Summary!#REF!*100 -> #REF! | I14: =#REF!/Summary!#REF!*100 -> #REF! | ... AI14: =#REF!/Summary!#REF!*100 -> #REF! | AJ14: =#REF!/Summary!B14*100 -> #REF! | AK14: =#REF!/Summary!C14*100 -> #REF! | AL14: =#REF!/Summary!D14*100 -> #REF! | AM14: =#REF!/Summary!E14*100 -> #REF! | AN14: =#REF!/Summary!F14*100 -> #REF! | AO14: =#REF!/Summary!G14*100 -> #REF! | AP14: =#REF!/Summary!H14*100 -> #REF! | AQ14: =#REF!/Summary!I14*100 -> #REF!
A15: Agriculture, Forestry & Fishing | B15: =#REF!/Summary!#REF!*100 -> #REF! | C15: =#REF!/Summary!#REF!*100 -> #REF! | D15: =#REF!/Summary!#REF!*100 -> #REF! | E15: =#REF!/Summary!#REF!*100 -> #REF! | F15: =#REF!/Summary!#REF!*100 -> #REF! | G15: =#REF!/Summary!#REF!*100 -> #REF! | H15: =#REF!/Summary!#REF!*100 -> #REF! | I15: =#REF!/Summary!#REF!*100 -> #REF! | ... AI15: =#REF!/Summary!#REF!*100 -> #REF! | AJ15: =#REF!/Summary!B15*100 -> #REF! | AK15: =#REF!/Summary!C15*100 -> #REF! | AL15: =#REF!/Summary!D15*100 -> #REF! | AM15: =#REF!/Summary!E15*100 -> #REF! | AN15: =#REF!/Summary!F15*100 -> #REF! | AO15: =#REF!/Summary!G15*100 -> #REF! | AP15: =#REF!/Summary!H15*100 -> #REF! | AQ15: =#REF!/Summary!I15*100 -> #REF!
A16: Industry | B16: =#REF!/Summary!#REF!*100 -> #REF! | C16: =#REF!/Summary!#REF!*100 -> #REF! | D16: =#REF!/Summary!#REF!*100 -> #REF! | E16: =#REF!/Summary!#REF!*100 -> #REF! | F16: =#REF!/Summary!#REF!*100 -> #REF! | G16: =#REF!/Summary!#REF!*100 -> #REF! | H16: =#REF!/Summary!#REF!*100 -> #REF! | I16: =#REF!/Summary!#REF!*100 -> #REF! | ... AI16: =#REF!/Summary!#REF!*100 -> #REF! | AJ16: =#REF!/Summary!B16*100 -> #REF! | AK16: =#REF!/Summary!C16*100 -> #REF! | AL16: =#REF!/Summary!D16*100 -> #REF! | AM16: =#REF!/Summary!E16*100 -> #REF! | AN16: =#REF!/Summary!F16*100 -> #REF! | AO16: =#REF!/Summary!G16*100 -> #REF! | AP16: =#REF!/Summary!H16*100 -> #REF! | AQ16: =#REF!/Summary!I16*100 -> #REF!
A17: Services | B17: =#REF!/Summary!#REF!*100 -> #REF! | C17: =#REF!/Summary!#REF!*100 -> #REF! | D17: =#REF!/Summary!#REF!*100 -> #REF! | E17: =#REF!/Summary!#REF!*100 -> #REF! | F17: =#REF!/Summary!#REF!*100 -> #REF! | G17: =#REF!/Summary!#REF!*100 -> #REF! | H17: =#REF!/Summary!#REF!*100 -> #REF! | I17: =#REF!/Summary!#REF!*100 -> #REF! | ... AI17: =#REF!/Summary!#REF!*100 -> #REF! | AJ17: =#REF!/Summary!B17*100 -> #REF! | AK17: =#REF!/Summary!C17*100 -> #REF! | AL17: =#REF!/Summary!D17*100 -> #REF! | AM17: =#REF!/Summary!E17*100 -> #REF! | AN17: =#REF!/Summary!F17*100 -> #REF! | AO17: =#REF!/Summary!G17*100 -> #REF! | AP17: =#REF!/Summary!H17*100 -> #REF! | AQ17: =#REF!/Summary!I17*100 -> #REF!
A18: Adjustments
A19: Taxes on products | B19: =#REF!/Summary!#REF!*100 -> #REF! | C19: =#REF!/Summary!#REF!*100 -> #REF! | D19: =#REF!/Summary!#REF!*100 -> #REF! | E19: =#REF!/Summary!#REF!*100 -> #REF! | F19: =#REF!/Summary!#REF!*100 -> #REF! | G19: =#REF!/Summary!#REF!*100 -> #REF! | H19: =#REF!/Summary!#REF!*100 -> #REF! | I19: =#REF!/Summary!#REF!*100 -> #REF! | ... AI19: =#REF!/Summary!#REF!*100 -> #REF! | AJ19: =#REF!/Summary!B19*100 -> #REF! | AK19: =#REF!/Summary!C19*100 -> #REF! | AL19: =#REF!/Summary!D19*100 -> #REF! | AM19: =#REF!/Summary!E19*100 -> #REF! | AN19: =#REF!/Summary!F19*100 -> #REF! | AO19: =#REF!/Summary!G19*100 -> #REF! | AP19: =#REF!/Summary!H19*100 -> #REF! | AQ19: =#REF!/Summary!I19*100 -> #REF!
A21: TREND CYCLE ESTIMATES
A22: GDP at market prices | B22: =#REF!/Summary!#REF!*100 -> #REF! | C22: =#REF!/Summary!#REF!*100 -> #REF! | D22: =#REF!/Summary!#REF!*100 -> #REF! | E22: =#REF!/Summary!#REF!*100 -> #REF! | F22: =#REF!/Summary!#REF!*100 -> #REF! | G22: =#REF!/Summary!#REF!*100 -> #REF! | H22: =#REF!/Summary!#REF!*100 -> #REF! | I22: =#REF!/Summary!#REF!*100 -> #REF! | ... AI22: =#REF!/Summary!#REF!*100 -> #REF! | AJ22: =#REF!/Summary!B22*100 -> #REF! | AK22: =#REF!/Summary!C22*100 -> #REF! | AL22: =#REF!/Summary!D22*100 -> #REF! | AM22: =#REF!/Summary!E22*100 -> #REF! | AN22: =#REF!/Summary!F22*100 -> #REF! | AO22: =#REF!/Summary!G22*100 -> #REF! | AP22: =#REF!/Summary!H22*100 -> #REF! | AQ22: =#REF!/Summary!I22*100 -> #REF!
A23: Agriculture, Forestry & Fishing | B23: =#REF!/Summary!#REF!*100 -> #REF! | C23: =#REF!/Summary!#REF!*100 -> #REF! | D23: =#REF!/Summary!#REF!*100 -> #REF! | E23: =#REF!/Summary!#REF!*100 -> #REF! | F23: =#REF!/Summary!#REF!*100 -> #REF! | G23: =#REF!/Summary!#REF!*100 -> #REF! | H23: =#REF!/Summary!#REF!*100 -> #REF! | I23: =#REF!/Summary!#REF!*100 -> #REF! | ... AI23: =#REF!/Summary!#REF!*100 -> #REF! | AJ23: =#REF!/Summary!B23*100 -> #REF! | AK23: =#REF!/Summary!C23*100 -> #REF! | AL23: =#REF!/Summary!D23*100 -> #REF! | AM23: =#REF!/Summary!E23*100 -> #REF! | AN23: =#REF!/Summary!F23*100 -> #REF! | AO23: =#REF!/Summary!G23*100 -> #REF! | AP23: =#REF!/Summary!H23*100 -> #REF! | AQ23: =#REF!/Summary!I23*100 -> #REF!
A24: Industry | B24: =#REF!/Summary!#REF!*100 -> #REF! | C24: =#REF!/Summary!#REF!*100 -> #REF! | D24: =#REF!/Summary!#REF!*100 -> #REF! | E24: =#REF!/Summary!#REF!*100 -> #REF! | F24: =#REF!/Summary!#REF!*100 -> #REF! | G24: =#REF!/Summary!#REF!*100 -> #REF! | H24: =#REF!/Summary!#REF!*100 -> #REF! | I24: =#REF!/Summary!#REF!*100 -> #REF! | ... AI24: =#REF!/Summary!#REF!*100 -> #REF! | AJ24: =#REF!/Summary!B24*100 -> #REF! | AK24: =#REF!/Summary!C24*100 -> #REF! | AL24: =#REF!/Summary!D24*100 -> #REF! | AM24: =#REF!/Summary!E24*100 -> #REF! | AN24: =#REF!/Summary!F24*100 -> #REF! | AO24: =#REF!/Summary!G24*100 -> #REF! | AP24: =#REF!/Summary!H24*100 -> #REF! | AQ24: =#REF!/Summary!I24*100 -> #REF!
A25: Services | B25: =#REF!/Summary!#REF!*100 -> #REF! | C25: =#REF!/Summary!#REF!*100 -> #REF! | D25: =#REF!/Summary!#REF!*100 -> #REF! | E25: =#REF!/Summary!#REF!*100 -> #REF! | F25: =#REF!/Summary!#REF!*100 -> #REF! | G25: =#REF!/Summary!#REF!*100 -> #REF! | H25: =#REF!/Summary!#REF!*100 -> #REF! | I25: =#REF!/Summary!#REF!*100 -> #REF! | ... AI25: =#REF!/Summary!#REF!*100 -> #REF! | AJ25: =#REF!/Summary!B25*100 -> #REF! | AK25: =#REF!/Summary!C25*100 -> #REF! | AL25: =#REF!/Summary!D25*100 -> #REF! | AM25: =#REF!/Summary!E25*100 -> #REF! | AN25: =#REF!/Summary!F25*100 -> #REF! | AO25: =#REF!/Summary!G25*100 -> #REF! | AP25: =#REF!/Summary!H25*100 -> #REF! | AQ25: =#REF!/Summary!I25*100 -> #REF!
A26: Adjustments
A27: Taxes on products | B27: =#REF!/Summary!#REF!*100 -> #REF! | C27: =#REF!/Summary!#REF!*100 -> #REF! | D27: =#REF!/Summary!#REF!*100 -> #REF! | E27: =#REF!/Summary!#REF!*100 -> #REF! | F27: =#REF!/Summary!#REF!*100 -> #REF! | G27: =#REF!/Summary!#REF!*100 -> #REF! | H27: =#REF!/Summary!#REF!*100 -> #REF! | I27: =#REF!/Summary!#REF!*100 -> #REF! | ... AI27: =#REF!/Summary!#REF!*100 -> #REF! | AJ27: =#REF!/Summary!B27*100 -> #REF! | AK27: =#REF!/Summary!C27*100 -> #REF! | AL27: =#REF!/Summary!D27*100 -> #REF! | AM27: =#REF!/Summary!E27*100 -> #REF! | AN27: =#REF!/Summary!F27*100 -> #REF! | AO27: =#REF!/Summary!G27*100 -> #REF! | AP27: =#REF!/Summary!H27*100 -> #REF! | AQ27: =#REF!/Summary!I27*100 -> #REF!
A28: Uganda Bureau of Statistics
X30: Table 4: Summary of QGDP at constant prices, PERCENTAGE SHARE, 2013/14-2017/18
B31: 2007/08 | D31: 2008/09 | H31: 2009/10 | L31: 2010/11 | P31: 2011/12 | U31: 2012/13 | X31: 2013/14 | AB31: 2014/15 | AF31: 2015/16 | AJ31: 2016/17 | AN31: 2017/18
A32: ACTIVITY | B32: Q3 | C32: Q4 | D32: Q1 | E32: Q2 | F32: Q3 | G32: Q4 | H32: Q1 | I32: Q2 | J32: Q3 | K32: Q4 | L32: Q1 | M32: Q2 | N32: Q3 | O32: Q4 | P32: Q1 | Q32: Q2 | R32: Q3 | S32: Q4 | T32: Q1 | U32: Q2 | V32: Q3 | W32: Q4 | X32: Q1 | Y32: Q2 | Z32: Q3 | AA32: Q4 | AB32: Q1 | AC32: Q2 | AD32: Q3 | AE32: Q4 | AF32: Q1 | AG32: Q2 | AH32: Q3 | AI32: Q4 | AJ32: Q1 | AK32: Q2 | AL32: Q3 | AM32: Q4 | AN32: Q1 | AO32: Q2 | AP32: Q3 | AQ32: Q4
A33: ORIGINAL ESTIMATES
A34: GDP at market prices | B34: =Summary!#REF!/Summary!#REF!*100 -> #REF! | C34: =Summary!#REF!/Summary!#REF!*100 -> #REF! | D34: =Summary!#REF!/Summary!#REF!*100 -> #REF! | E34: =Summary!#REF!/Summary!#REF!*100 -> #REF! | F34: =Summary!#REF!/Summary!#REF!*100 -> #REF! | G34: =Summary!#REF!/Summary!#REF!*100 -> #REF! | H34: =Summary!#REF!/Summary!#REF!*100 -> #REF! | I34: =Summary!#REF!/Summary!#REF!*100 -> #REF! | J34: =Summary!#REF!/Summary!#REF!*100 -> #REF! | K34: =SUM(K35:K39) -> #REF! | L34: =SUM(L35:L39) -> #REF! | M34: =SUM(M35:M39) -> #REF! | N34: =SUM(N35:N39) -> #REF! | O34: =SUM(O35:O39) -> #REF! | P34: =SUM(P35:P39) -> #REF! | Q34: =SUM(Q35:Q39) -> #REF! | R34: =SUM(R35:R39) -> #REF! | ... AQ34: =SUM(AQ35:AQ39) -> 100
A35: Agriculture, Forestry & Fishing | B35: =Summary!#REF!/Summary!#REF!*100 -> #REF! | C35: =Summary!#REF!/Summary!#REF!*100 -> #REF! | D35: =Summary!#REF!/Summary!#REF!*100 -> #REF! | E35: =Summary!#REF!/Summary!#REF!*100 -> #REF! | F35: =Summary!#REF!/Summary!#REF!*100 -> #REF! | G35: =Summary!#REF!/Summary!#REF!*100 -> #REF! | H35: =Summary!#REF!/Summary!#REF!*100 -> #REF! | I35: =Summary!#REF!/Summary!#REF!*100 -> #REF! | ... AI35: =Summary!#REF!/Summary!#REF!*100 -> #REF! | AJ35: =Summary!B7/Summary!B$6*100 -> 28.037654 | AK35: =Summary!C7/Summary!C$6*100 -> 22.963232 | AL35: =Summary!D7/Summary!D$6*100 -> 20.424136 | AM35: =Summary!E7/Summary!E$6*100 -> 22.054985 | AN35: =Summary!F7/Summary!F$6*100 -> 28.54441 | AO35: =Summary!G7/Summary!G$6*100 -> 21.87934 | AP35: =Summary!H7/Summary!H$6*100 -> 19.871348 | AQ35: =Summary!I7/Summary!I$6*100 -> 21.316147
A36: Industry | B36: =Summary!#REF!/Summary!#REF!*100 -> #REF! | C36: =Summary!#REF!/Summary!#REF!*100 -> #REF! | D36: =Summary!#REF!/Summary!#REF!*100 -> #REF! | E36: =Summary!#REF!/Summary!#REF!*100 -> #REF! | F36: =Summary!#REF!/Summary!#REF!*100 -> #REF! | G36: =Summary!#REF!/Summary!#REF!*100 -> #REF! | H36: =Summary!#REF!/Summary!#REF!*100 -> #REF! | I36: =Summary!#REF!/Summary!#REF!*100 -> #REF! | ... AI36: =Summary!#REF!/Summary!#REF!*100 -> #REF! | AJ36: =Summary!B8/Summary!B$6*100 -> 23.685672 | AK36: =Summary!C8/Summary!C$6*100 -> 26.707319 | AL36: =Summary!D8/Summary!D$6*100 -> 27.840592 | AM36: =Summary!E8/Summary!E$6*100 -> 26.087901 | AN36: =Summary!F8/Summary!F$6*100 -> 23.186179 | AO36: =Summary!G8/Summary!G$6*100 -> 25.807515 | AP36: =Summary!H8/Summary!H$6*100 -> 27.256037 | AQ36: =Summary!I8/Summary!I$6*100 -> 26.685471
A37: Services | B37: =Summary!#REF!/Summary!#REF!*100 -> #REF! | C37: =Summary!#REF!/Summary!#REF!*100 -> #REF! | D37: =Summary!#REF!/Summary!#REF!*100 -> #REF! | E37: =Summary!#REF!/Summary!#REF!*100 -> #REF! | F37: =Summary!#REF!/Summary!#REF!*100 -> #REF! | G37: =Summary!#REF!/Summary!#REF!*100 -> #REF! | H37: =Summary!#REF!/Summary!#REF!*100 -> #REF! | I37: =Summary!#REF!/Summary!#REF!*100 -> #REF! | ... AI37: =Summary!#REF!/Summary!#REF!*100 -> #REF! | AJ37: =Summary!B9/Summary!B$6*100 -> 41.773507 | AK37: =Summary!C9/Summary!C$6*100 -> 43.498031 | AL37: =Summary!D9/Summary!D$6*100 -> 44.309022 | AM37: =Summary!E9/Summary!E$6*100 -> 44.453427 | AN37: =Summary!F9/Summary!F$6*100 -> 41.798402 | AO37: =Summary!G9/Summary!G$6*100 -> 45.226965 | AP37: =Summary!H9/Summary!H$6*100 -> 45.87259 | AQ37: =Summary!I9/Summary!I$6*100 -> 44.888904
A38: Adjustments
A39: Taxes on products | B39: =Summary!#REF!/Summary!#REF!*100 -> #REF! | C39: =Summary!#REF!/Summary!#REF!*100 -> #REF! | D39: =Summary!#REF!/Summary!#REF!*100 -> #REF! | E39: =Summary!#REF!/Summary!#REF!*100 -> #REF! | F39: =Summary!#REF!/Summary!#REF!*100 -> #REF! | G39: =Summary!#REF!/Summary!#REF!*100 -> #REF! | H39: =Summary!#REF!/Summary!#REF!*100 -> #REF! | I39: =Summary!#REF!/Summary!#REF!*100 -> #REF! | ... AI39: =Summary!#REF!/Summary!#REF!*100 -> #REF! | AJ39: =Summary!B11/Summary!B$6*100 -> 6.5031669 | AK39: =Summary!C11/Summary!C$6*100 -> 6.8314186 | AL39: =Summary!D11/Summary!D$6*100 -> 7.4262494 | AM39: =Summary!E11/Summary!E$6*100 -> 7.4036868 | AN39: =Summary!F11/Summary!F$6*100 -> 6.4710095 | AO39: =Summary!G11/Summary!G$6*100 -> 7.0861789 | AP39: =Summary!H11/Summary!H$6*100 -> 7.0000257 | AQ39: =Summary!I11/Summary!I$6*100 -> 7.1094781
A41: SEASONALLY ADJUSTED ESTIMATES
A42: GDP at market prices | B42: =Summary!#REF!/Summary!#REF!*100 -> #REF! | C42: =Summary!#REF!/Summary!#REF!*100 -> #REF! | D42: =Summary!#REF!/Summary!#REF!*100 -> #REF! | E42: =Summary!#REF!/Summary!#REF!*100 -> #REF! | F42: =Summary!#REF!/Summary!#REF!*100 -> #REF! | G42: =Summary!#REF!/Summary!#REF!*100 -> #REF! | H42: =Summary!#REF!/Summary!#REF!*100 -> #REF! | I42: =Summary!#REF!/Summary!#REF!*100 -> #REF! | J42: =Summary!#REF!/Summary!#REF!*100 -> #REF! | K42: =SUM(K43:K47) -> #REF! | L42: =SUM(L43:L47) -> #REF! | M42: =SUM(M43:M47) -> #REF! | N42: =SUM(N43:N47) -> #REF! | O42: =SUM(O43:O47) -> #REF! | P42: =SUM(P43:P47) -> #REF! | Q42: =SUM(Q43:Q47) -> #REF! | R42: =SUM(R43:R47) -> #REF! | ... AQ42: =SUM(AQ43:AQ47) -> 100
A43: Agriculture, Forestry & Fishing | B43: =Summary!#REF!/Summary!#REF!*100 -> #REF! | C43: =Summary!#REF!/Summary!#REF!*100 -> #REF! | D43: =Summary!#REF!/Summary!#REF!*100 -> #REF! | E43: =Summary!#REF!/Summary!#REF!*100 -> #REF! | F43: =Summary!#REF!/Summary!#REF!*100 -> #REF! | G43: =Summary!#REF!/Summary!#REF!*100 -> #REF! | H43: =Summary!#REF!/Summary!#REF!*100 -> #REF! | I43: =Summary!#REF!/Summary!#REF!*100 -> #REF! | ... AI43: =Summary!#REF!/Summary!#REF!*100 -> #REF! | AJ43: =Summary!B15/Summary!B$14*100 -> 23.141435 | AK43: =Summary!C15/Summary!C$14*100 -> 23.733443 | AL43: =Summary!D15/Summary!D$14*100 -> 23.832955 | AM43: =Summary!E15/Summary!E$14*100 -> 23.47966 | AN43: =Summary!F15/Summary!F$14*100 -> 23.41497 | AO43: =Summary!G15/Summary!G$14*100 -> 22.874529 | AP43: =Summary!H15/Summary!H$14*100 -> 23.563422 | AQ43: =Summary!I15/Summary!I$14*100 -> 22.629999
A44: Industry | B44: =Summary!#REF!/Summary!#REF!*100 -> #REF! | C44: =Summary!#REF!/Summary!#REF!*100 -> #REF! | D44: =Summary!#REF!/Summary!#REF!*100 -> #REF! | E44: =Summary!#REF!/Summary!#REF!*100 -> #REF! | F44: =Summary!#REF!/Summary!#REF!*100 -> #REF! | G44: =Summary!#REF!/Summary!#REF!*100 -> #REF! | H44: =Summary!#REF!/Summary!#REF!*100 -> #REF! | I44: =Summary!#REF!/Summary!#REF!*100 -> #REF! | ... AI44: =Summary!#REF!/Summary!#REF!*100 -> #REF! | AJ44: =Summary!B16/Summary!B$14*100 -> 25.779841 | AK44: =Summary!C16/Summary!C$14*100 -> 26.337324 | AL44: =Summary!D16/Summary!D$14*100 -> 26.263783 | AM44: =Summary!E16/Summary!E$14*100 -> 25.615754 | AN44: =Summary!F16/Summary!F$14*100 -> 25.330982 | AO44: =Summary!G16/Summary!G$14*100 -> 25.297642 | AP44: =Summary!H16/Summary!H$14*100 -> 25.672472 | AQ44: =Summary!I16/Summary!I$14*100 -> 26.257305
A45: Services | B45: =Summary!#REF!/Summary!#REF!*100 -> #REF! | C45: =Summary!#REF!/Summary!#REF!*100 -> #REF! | D45: =Summary!#REF!/Summary!#REF!*100 -> #REF! | E45: =Summary!#REF!/Summary!#REF!*100 -> #REF! | F45: =Summary!#REF!/Summary!#REF!*100 -> #REF! | G45: =Summary!#REF!/Summary!#REF!*100 -> #REF! | H45: =Summary!#REF!/Summary!#REF!*100 -> #REF! | I45: =Summary!#REF!/Summary!#REF!*100 -> #REF! | ... AI45: =Summary!#REF!/Summary!#REF!*100 -> #REF! | AJ45: =Summary!B17/Summary!B$14*100 -> 43.950024 | AK45: =Summary!C17/Summary!C$14*100 -> 43.199067 | AL45: =Summary!D17/Summary!D$14*100 -> 42.77316 | AM45: =Summary!E17/Summary!E$14*100 -> 43.807962 | AN45: =Summary!F17/Summary!F$14*100 -> 44.144299 | AO45: =Summary!G17/Summary!G$14*100 -> 44.86476 | AP45: =Summary!H17/Summary!H$14*100 -> 44.055858 | AQ45: =Summary!I17/Summary!I$14*100 -> 44.273692
...

Sheet Original_VA
A1: Table 3: ORIGINAL UNADJUSTED Value Added by activity at constant 2016/17 prices, BILLION SHILLINGS, 2016/17-2025/26
A3: Year | B3: 2016/17 | F3: 2017/18 | J3: 2018/19 | N3: 2019/20 | R3: 2020/21 | V3: 2021/22 | Z3: 2022/23 | AD3: 2023/24 | AH3: 2024/25 | AL3: 2025/26
A4: Period | B4: Q1 | C4: Q2 | D4: Q3 | E4: Q4 | F4: Q1 | G4: Q2 | H4: Q3 | I4: Q4 | J4: Q1 | K4: Q2 | L4: Q3 | M4: Q4 | N4: Q1 | O4: Q2 | P4: Q3 | Q4: Q4 | R4: Q1 | S4: Q2 | T4: Q3 | U4: Q4 | V4: Q1 | W4: Q2 | X4: Q3 | Y4: Q4 | Z4: Q1 | AA4: Q2 | AB4: Q3 | AC4: Q4 | AD4: Q1 | AE4: Q2 | AF4: Q3 | AG4: Q4 | AH4: Q1 | AI4: Q2 | AJ4: Q3 | AK4: Q4 | AL4: Q1 | AM4: Q2
A5: GDP AT MARKET PRICES | B5: 28577.247 | C5: 26610.18 | D5: 26240.178 | E5: 27090.435 | F5: 30772.237 | G5: 28335.28 | H5: 27653.331 | I5: 28598.087 | J5: 32487.642 | K5: 29958.631 | L5: 29773.235 | M5: 30567.095 | N5: 34943.779 | O5: 32466.458 | P5: 30130.072 | Q5: 28870.102 | R5: 34802.923 | S5: 32477.008 | T5: 30975.024 | U5: 32626.063 | V5: 35622.436 | W5: 34024.49 | X5: 32716.662 | Y5: 34522.28 | Z5: 38746.737 | AA5: 35492.013 | AB5: 33446.228 | AC5: 36506.452 | AD5: 41068.072 | AE5: 37544.31 | AF5: 35728.791 | AG5: 38581.884 | AH5: 43605.836 | AI5: 39557.991 | AJ5: 38727.987 | AK5: 40714.044 | AL5: 45718.884 | AM5: 42903.876
A6: AGRICULTURE,FORESTRY&FISHING | B6: 8012.3898 | C6: 6110.5575 | D6: 5359.3298 | E6: 5974.7915 | F6: 8783.7536 | G6: 6199.5724 | H6: 5495.0897 | I6: 6096.0101 | J6: 8974.6097 | K6: 6448.4413 | L6: 5935.2774 | M6: 6628.7289 | N6: 9517.4185 | O6: 6941.2508 | P6: 5858.4835 | Q6: 7019.6669 | R6: 10178.838 | S6: 7480.0514 | T6: 5874.7257 | U6: 7070.5839 | V6: 10624.95 | W6: 7330.892 | X6: 6120.4467 | Y6: 7804.9868 | Z6: 11088.263 | AA6: 8197.4364 | AB6: 6452.1008 | AC6: 7589.8403 | AD6: 11715.27 | AE6: 8365.8311 | AF6: 6712.9791 | AG6: 8392.5624 | AH6: 12457.04 | AI6: 9018.0558 | AJ6: 7404.8569 | AK6: 8683.3829 | AL6: 12839.64 | AM6: 9809.0589
A7: Cash crops | B7: 503.80349 | C7: 751.47235 | D7: 756.6638 | E7: 540.01006 | F7: 711.49019 | G7: 721.04285 | H7: 772.20685 | I7: 498.20843 | J7: 708.23323 | K7: 768.35837 | L7: 790.47225 | M7: 563.82244 | N7: 726.02296 | O7: 837.1285 | P7: 928.12524 | Q7: 560.87771 | R7: 782.35957 | S7: 933.39018 | T7: 1033.3276 | U7: 683.9495 | V7: 965.22972 | W7: 980.0504 | X7: 993.72889 | Y7: 688.45779 | Z7: 969.15812 | AA7: 928.29383 | AB7: 1072.7337 | AC7: 681.86824 | AD7: 1030.9453 | AE7: 1070.8634 | AF7: 1245.7712 | AG7: 753.11773 | AH7: 1200.8309 | AI7: 1173.3745 | AJ7: 1357.3298 | AK7: 833.80664 | AL7: 1285.3573 | AM7: 1320.8624
A8: Food crops | B8: 5158.2444 | C8: 2956.6065 | D8: 2216.3688 | E8: 3063.7253 | F8: 5764.4524 | G8: 3189.0326 | H8: 2406.5075 | I8: 3180.2595 | J8: 5806.2349 | K8: 3120.4628 | L8: 2491.5732 | M8: 3355.7462 | N8: 6087.3682 | O8: 3386.3637 | P8: 2210.2087 | Q8: 3770.8716 | R8: 6729.3932 | S8: 3733.7504 | T8: 2032.2914 | U8: 3595.1715 | V8: 6847.8466 | W8: 3553.494 | X8: 2141.0816 | Y8: 4113.2181 | Z8: 7367.019 | AA8: 4243.1851 | AB8: 2047.1733 | AC8: 3777.0373 | AD8: 7740.0659 | AE8: 4232.3299 | AF8: 2190.283 | AG8: 4166.6736 | AH8: 8152.8624 | AI8: 4529.7878 | AJ8: 2262.5053 | AK8: 4257.0001 | AL8: 8108.2689 | AM8: 4878.8645
A9: Livestock | B9: 803.94776 | C9: 820.59322 | D9: 836.92932 | E9: 847.61996 | F9: 869.7722 | G9: 875.22137 | H9: 895.75739 | I9: 904.19998 | J9: 927.06886 | K9: 942.41424 | L9: 958.71971 | M9: 977.13017 | N9: 999.62611 | O9: 1016.5699 | P9: 1037.6779 | Q9: 1051.9475 | R9: 1075.0903 | S9: 1093.5814 | T9: 1117.645 | U9: 1139.3805 | V9: 1164.9148 | W9: 1183.7106 | X9: 1209.2184 | Y9: 1235.4276 | Z9: 1266.6927 | AA9: 1289.0045 | AB9: 1324.7443 | AC9: 1336.3725 | AD9: 1364.9638 | AE9: 1392.5445 | AF9: 1421.1592 | AG9: 1449.5255 | AH9: 1480.2991 | AI9: 1512.2661 | AJ9: 1550.6613 | AK9: 1577.5316 | AL9: 1617.3459 | AM9: 1651.731
A10: Agriculture Support Services | B10: 6.2837288 | C10: 3.325037 | D10: 2.0494802 | E10: 4.8141938 | F10: 6.2956095 | G10: 3.2755887 | H10: 2.0080248 | I10: 4.8329083 | J10: 6.6083068 | K10: 3.5884171 | L10: 2.1829168 | M10: 5.4791027 | N10: 7.7829336 | O10: 4.3860543 | P10: 2.1540787 | Q10: 4.6823231 | R10: 7.2284747 | S10: 3.9801091 | T10: 2.7383126 | U10: 5.4484674 | V10: 7.7592654 | W10: 4.0780685 | X10: 2.8418931 | Y10: 5.5823033 | Z10: 7.9640725 | AA10: 4.2517334 | AB10: 2.8588657 | AC10: 5.6398941 | AD10: 8.3887802 | AE10: 4.5610538 | AF10: 3.0962641 | AG10: 6.1329907 | AH10: 8.7481039 | AI10: 4.4104034 | AJ10: 3.0707098 | AK10: 7.1536239 | AL10: 7.7163285 | AM10: 4.4194806
A11: Forestry | B11: 977.93029 | C11: 992.65352 | D11: 1004.7215 | E11: 1027.2691 | F11: 1007.3811 | G11: 1003.7501 | H11: 1044.0648 | I11: 1082.2855 | J11: 1044.1093 | K11: 1056.6287 | L11: 1070.8268 | M11: 1114.9791 | N11: 1086.4176 | O11: 1108.061 | P11: 1120.3878 | Q11: 1111.3554 | R11: 1056.878 | S11: 1149.2585 | T11: 1181.6024 | U11: 1168.9939 | V11: 1107.6165 | W11: 1115.7609 | X11: 1243.7005 | Y11: 1233.5857 | Z11: 1152.8066 | AA11: 1158.8936 | AB11: 1275.3325 | AC11: 1260.9317 | AD11: 1214.7921 | AE11: 1190.4314 | AF11: 1200.1467 | AG11: 1391.5844 | AH11: 1260.4901 | AI11: 1251.7752 | AJ11: 1287.4128 | AK11: 1362.3897 | AL11: 1383.2163 | AM11: 1355.0945
A12: Fishing | B12: 562.18016 | C12: 585.90691 | D12: 542.59683 | E12: 491.35281 | F12: 424.36218 | G12: 407.24998 | H12: 374.54516 | I12: 426.22385 | J12: 482.35514 | K12: 556.98883 | L12: 621.50255 | M12: 611.57191 | N12: 610.20066 | O12: 588.74175 | P12: 559.92985 | Q12: 519.93242 | R12: 527.88856 | S12: 566.09095 | T12: 507.12106 | U12: 477.64002 | V12: 531.58287 | W12: 493.79799 | X12: 529.87529 | Y12: 528.71517 | Z12: 324.62227 | AA12: 573.80759 | AB12: 729.25809 | AC12: 527.99078 | AD12: 356.11407 | AE12: 475.10096 | AF12: 652.52279 | AG12: 625.52817 | AH12: 353.80898 | AI12: 546.44166 | AJ12: 943.87711 | AK12: 645.50127 | AL12: 437.73547 | AM12: 598.08703
A13: INDUSTRY | B13: 6768.7131 | C13: 7106.8656 | D13: 7305.421 | E13: 7067.3259 | F13: 7134.9059 | G13: 7312.6318 | H13: 7537.2021 | I13: 7631.5343 | J13: 7779.6918 | K13: 8068.1838 | L13: 8243.5123 | M13: 8201.8824 | N13: 8570.2406 | O13: 8886.3356 | P13: 8486.7958 | Q13: 7398.8511 | R13: 8381.1058 | S13: 8755.7883 | T13: 8669.0779 | U13: 8693.4802 | V13: 8370.9467 | W13: 9440.8925 | X13: 9148.3498 | Y13: 9308.0376 | Z13: 9399.6503 | AA13: 9216.6242 | AB13: 9213.4013 | AC13: 9899.9765 | AD13: 10329.779 | AE13: 9629.9206 | AF13: 9832.8272 | AG13: 10008.679 | AH13: 10858.986 | AI13: 10366.745 | AJ13: 10560.436 | AK13: 10766.195 | AL13: 11507.782 | AM13: 11637.499
A14: Mining & quarrying | B14: 282.95293 | C14: 276.59929 | D14: 375.75679 | E14: 401.80833 | F14: 319.7555 | G14: 224.76187 | H14: 339.81152 | I14: 399.51644 | J14: 397.45267 | K14: 270.96658 | L14: 456.76541 | M14: 382.76325 | N14: 454.84011 | O14: 474.18067 | P14: 511.09849 | Q14: 317.00352 | R14: 645.34983 | S14: 468.64606 | T14: 394.79031 | U14: 370.03532 | V14: 281.63209 | W14: 699.91945 | X14: 555.65764 | Y14: 685.74265 | Z14: 531.92636 | AA14: 337.30454 | AB14: 418.13259 | AC14: 1047.8039 | AD14: 1057.992 | AE14: 661.67504 | AF14: 435.10339 | AG14: 254.56755 | AH14: 967.23315 | AI14: 725.91079 | AJ14: 433.19398 | AK14: 365.58098 | AL14: 866.42074 | AM14: 924.2791
A15: Manufacturing | B15: 4040.705 | C15: 4238.5858 | D15: 4435.5484 | E15: 4130.4121 | F15: 4261.464 | G15: 4439.8418 | H15: 4503.4215 | I15: 4419.5601 | J15: 4561.6635 | K15: 4852.9223 | L15: 4835.1147 | M15: 4731.8722 | N15: 5096.6336 | O15: 5278.1396 | P15: 4784.5996 | Q15: 4060.5317 | R15: 4909.3533 | S15: 5000.3958 | T15: 4890.4733 | U15: 4843.5145 | V15: 4617.2239 | W15: 5323.9039 | X15: 5273.5154 | Y15: 5182.5961 | Z15: 5339.1513 | AA15: 5395.2734 | AB15: 5202.2022 | AC15: 5098.4633 | AD15: 5590.3484 | AE15: 5307.7672 | AF15: 5461.8901 | AG15: 5659.4204 | AH15: 5935.8741 | AI15: 5719.2052 | AJ15: 5747.7099 | AK15: 5854.8503 | AL15: 6218.0588 | AM15: 6229.6419
A16: Electricity | B16: 330.50837 | C16: 338.39281 | D16: 360.04769 | E16: 350.52748 | F16: 365.87468 | G16: 364.64894 | H16: 366.75833 | I16: 356.45256 | J16: 365.71697 | K16: 363.9283 | L16: 374.53323 | M16: 385.58107 | N16: 410.67753 | O16: 420.90578 | P16: 438.26559 | Q16: 382.38906 | R16: 446.83511 | S16: 458.60371 | T16: 470.86524 | U16: 468.11348 | V16: 469.51958 | W16: 473.62344 | X16: 480.90714 | Y16: 478.24728 | Z16: 498.13323 | AA16: 511.1819 | AB16: 524.08967 | AC16: 529.54458 | AD16: 557.4673 | AE16: 553.71387 | AF16: 569.86152 | AG16: 565.92799 | AH16: 593.4025 | AI16: 611.79592 | AJ16: 646.30896 | AK16: 661.7343 | AL16: 749.36438 | AM16: 677.86404
... A33: Activities of Households | B33: 220.43437 | C33: 222.05653 | D33: 223.6473 | E33: 225.21208 | F33: 226.75658 | G33: 228.3158 | H33: 229.88331 | I33: 231.46596 | J33: 233.07033 | K33: 234.68168 | L33: 236.29337 | M33: 237.91141 | N33: 239.54242 | O33: 241.1751 | P33: 242.80326 | Q33: 244.43246 | R33: 246.06921 | S33: 247.72055 | T33: 249.44396 | U33: 251.18214 | V33: 252.87801 | W33: 254.57335 | X33: 256.32765 | Y33: 258.08109 | Z33: 259.77441 | AA33: 261.48299 | AB33: 263.3354 | AC33: 265.20368 | AD33: 266.95973 | AE33: 268.7154 | AF33: 270.60323 | AG33: 272.49078 | AH33: 274.24576 | AI33: 276.01332 | AJ33: 278.0007 | AK33: 280.00154 | AL33: 281.80886 | AM33: 281.80886
A35: ADJUSTMENTS
A36: Taxes on products | B36: 1858.4261 | C36: 1817.8528 | D36: 1948.6611 | E36: 2005.691 | F36: 1991.2744 | G36: 2007.8887 | H36: 1935.7403 | I36: 2033.1747 | J36: 1979.1119 | K36: 2073.2514 | L36: 2129.377 | M36: 2135.7379 | N36: 2197.3365 | O36: 2270.9524 | P36: 2114.9878 | Q36: 1601.8521 | R36: 2123.5437 | S36: 2166.7043 | T36: 2039.8093 | U36: 2366.598 | V36: 2087.3237 | W36: 2349.8691 | X36: 2484.895 | Y36: 2428.7012 | Z36: 2459.0041 | AA36: 2470.6617 | AB36: 2587.0261 | AC36: 2698.9015 | AD36: 2801.1416 | AE36: 2642.3794 | AF36: 2764.0558 | AG36: 2801.4262 | AH36: 3096.8575 | AI36: 2889.5255 | AJ36: 2914.9594 | AK36: 3024.8849 | AL36: 3200.5564 | AM36: 3095.8858
A37: Source: Uganda Bureau of Statistics

Sheet Original_Growth
A1: Table 4: ORIGINAL UNADJUSTED Value Added at constant 2016/17 prices, PERCENTAGE CHANGE, 2016/17-2025/26
B3: 2016/17 | F3: 2017/18 | J3: 2018/19 | N3: 2019/20 | R3: 2020/21 | V3: 2021/22 | Z3: 2022/23 | AD3: 2023/24 | AH3: 2024/25 | AL3: 2025/26
B4: Q1 | C4: Q2 | D4: Q3 | E4: Q4 | F4: Q1 | G4: Q2 | H4: Q3 | I4: Q4 | J4: Q1 | K4: Q2 | L4: Q3 | M4: Q4 | N4: Q1 | O4: Q2 | P4: Q3 | Q4: Q4 | R4: Q1 | S4: Q2 | T4: Q3 | U4: Q4 | V4: Q1 | W4: Q2 | X4: Q3 | Y4: Q4 | Z4: Q1 | AA4: Q2 | AB4: Q3 | AC4: Q4 | AD4: Q1 | AE4: Q2 | AF4: Q3 | AG4: Q4 | AH4: Q1 | AI4: Q2 | AJ4: Q3 | AK4: Q4 | AL4: Q1 | AM4: Q2
A5: GDP AT MARKET PRICES | B5: -0.26122599 | C5: 0.50756396 | D5: 6.7464548 | E5: 6.1811727 | F5: 7.6808998 | G5: 6.4828574 | H5: 5.3854549 | I5: 5.5652552 | J5: 5.5745218 | K5: 5.7290794 | L5: 7.6659989 | M5: 6.8851035 | N5: 7.5602194 | O5: 8.3709675 | P5: 1.1985158 | Q5: -5.5516965 | R5: -0.40309239 | S5: 0.032495737 | T5: 2.804345 | U5: 13.009861 | V5: 2.354724 | W5: 4.7648514 | X5: 5.6227189 | Y5: 5.811971 | Z5: 8.7705981 | AA5: 4.3131379 | AB5: 2.2299523 | AC5: 5.7475112 | AD5: 5.9910476 | AE5: 5.7824205 | AF5: 6.8245768 | AG5: 5.6851104 | AH5: 6.1794064 | AI5: 5.3634777 | AJ5: 8.394339 | AK5: 5.5263248 | AL5: 4.8457919 | AM5: 8.4581777
A6: AGRICULTURE,FORESTRY&FISHING | B6: 1.1733408 | C6: 3.2296506 | D6: 1.0636812 | E6: 6.0861995 | F6: 9.6271373 | G6: 1.4567401 | H6: 2.5331515 | I6: 2.0288347 | J6: 2.172831 | K6: 4.0142917 | L6: 8.010565 | M6: 8.7388102 | N6: 6.0482714 | O6: 7.6423041 | P6: -1.2938559 | Q6: 5.8976315 | R6: 6.9495696 | S6: 7.7622984 | T6: 0.27724211 | U6: 0.72534795 | V6: 4.382736 | W6: -1.9940967 | X6: 4.1826802 | Y6: 10.386736 | Z6: 4.3606145 | AA6: 11.82045 | AB6: 5.4187897 | AC6: -2.7565253 | AD6: 5.654692 | AE6: 2.0542364 | AF6: 4.0433085 | AG6: 10.57627 | AH6: 6.331648 | AI6: 7.796292 | AJ6: 10.306569 | AK6: 3.4652179 | AL6: 3.0713611 | AM6: 8.7713266
A7: Cash crops | B7: -16.007927 | C7: 23.751211 | D7: 12.020404 | E7: 19.986916 | F7: 41.223752 | G7: -4.0493176 | H7: 2.0541554 | I7: -7.7408987 | J7: -0.45776578 | K7: 6.5620954 | L7: 2.36535 | M7: 13.169991 | N7: 2.5118453 | O7: 8.9502677 | P7: 17.41402 | Q7: -0.52227954 | R7: 7.7596194 | S7: 11.499033 | T7: 11.334927 | U7: 21.942714 | V7: 23.374182 | W7: 4.9990053 | X7: -3.8321506 | Y7: 0.65915566 | Z7: 0.4069914 | AA7: -5.2810114 | AB7: 7.9503397 | AC7: -0.95714691 | AD7: 6.3753418 | AE7: 15.358235 | AF7: 16.13052 | AG7: 10.449158 | AH7: 16.47863 | AI7: 9.5727556 | AJ7: 8.954976 | AK7: 10.713984 | AL7: 7.0389932 | AM7: 12.569547
A8: Food crops | B8: 1.7376881 | C8: -3.4995387 | D8: 6.1821644 | E8: 6.4109612 | F8: 11.752214 | G8: 7.8612466 | H8: 8.578837 | I8: 3.8036746 | J8: 0.72483173 | K8: -2.1501749 | L8: 3.5348213 | M8: 5.5179991 | N8: 4.8419209 | O8: 8.5211992 | P8: -11.292646 | Q8: 12.370584 | R8: 10.54684 | S8: 10.2584 | T8: -8.0497943 | U8: -4.6594018 | V8: 1.7602391 | W8: -4.8277555 | X8: 5.3530803 | Y8: 14.409511 | Z8: 7.5815419 | AA8: 19.408815 | AB8: -4.386021 | AC8: -8.1731832 | AD8: 5.0637427 | AE8: -0.25582669 | AF8: 6.9905976 | AG8: 10.315924 | AH8: 5.3332431 | AI8: 7.0282315 | AJ8: 3.2973958 | AK8: 2.167834 | AL8: -0.5469674 | AM8: 7.7062476
A9: Livestock | B9: 5.6220551 | C9: 7.3369226 | D9: 8.0046056 | E9: 7.0651484 | F9: 8.1876515 | G9: 6.6571546 | H9: 7.0290372 | I9: 6.6751637 | J9: 6.5875482 | K9: 7.677242 | L9: 7.0289477 | M9: 8.065715 | N9: 7.8265223 | O9: 7.8686926 | P9: 8.2357916 | Q9: 7.6568416 | R9: 7.5492368 | S9: 7.5756165 | T9: 7.7063501 | U9: 8.311535 | V9: 8.3550688 | W9: 8.2416626 | X9: 8.1934317 | Y9: 8.4297719 | Z9: 8.7369443 | AA9: 8.8952394 | AB9: 9.5537611 | AC9: 8.1708417 | AD9: 7.7580832 | AE9: 8.032551 | AF9: 7.2780032 | AG9: 8.46718 | AH9: 8.4496924 | AI9: 8.5973316 | AJ9: 9.1124298 | AK9: 8.8308919 | AL9: 9.2580536 | AM9: 9.2222406
A10: Agriculture Support Services | B10: 1.7603391 | C10: 5.0997732 | D10: 4.9594275 | E10: 5.1449869 | F10: 0.18907177 | G10: -1.4871507 | H10: -2.0227286 | I10: 0.38873457 | J10: 4.9669107 | K10: 9.5502966 | L10: 8.709657 | M10: 13.370715 | N10: 17.775003 | O10: 22.228107 | P10: -1.3210824 | Q10: -14.542154 | R10: -7.1240347 | S10: -9.255361 | T10: 27.122216 | U10: 16.362482 | V10: 7.3430525 | W10: 2.4612239 | X10: 3.7826391 | Y10: 2.4563964 | Z10: 2.6395159 | AA10: 4.2585086 | AB10: 0.59723142 | AC10: 1.0316667 | AD10: 5.3327958 | AE10: 7.2751607 | AF10: 8.3039338 | AG10: 8.7430127 | AH10: 4.2833839 | AI10: -3.3029737 | AJ10: -0.82532569 | AK10: 16.641687 | AL10: -11.794275 | AM10: 0.20581178
A11: Forestry | B11: 9.2270813 | C11: 12.389945 | D11: -13.360354 | E11: 10.596833 | F11: 3.0115427 | G11: 1.1178658 | H11: 3.9158384 | I11: 5.3555936 | J11: 3.645907 | K11: 5.2681081 | L11: 2.5632508 | M11: 3.0207938 | N11: 4.0520984 | O11: 4.8675828 | P11: 4.6282912 | Q11: -0.32500304 | R11: -2.7189866 | S11: 3.7179826 | T11: 5.4636969 | U11: 5.186329 | V11: 4.8007818 | W11: -2.9147167 | X11: 5.2554205 | Y11: 5.5254169 | Z11: 4.0799476 | AA11: 3.8657717 | AB11: 2.5433767 | AC11: 2.2167842 | AD11: 5.376921 | AE11: 2.7213663 | AF11: -5.8953936 | AG11: 10.3616 | AH11: 3.761795 | AI11: 5.153076 | AJ11: 7.271286 | AK11: -2.0979444 | AL11: 9.7363837 | AM11: 8.2538254
A12: Fishing | B12: -4.204575 | C12: -1.9275876 | D12: -10.109137 | E12: -14.947848 | F12: -24.514914 | G12: -30.492374 | H12: -30.971737 | I12: -13.25503 | J12: 13.665911 | K12: 36.768289 | L12: 65.935276 | M12: 43.486083 | N12: 26.504438 | O12: 5.7008185 | P12: -9.9070707 | Q12: -14.984255 | R12: -13.489349 | S12: -3.8473233 | T12: -9.4313234 | U12: -8.1342105 | V12: 0.69982751 | W12: -12.770556 | X12: 4.4869431 | Y12: 10.69323 | Z12: -38.932895 | AA12: 16.202901 | AB12: 37.628249 | AC12: -0.13700969 | AD12: 9.7010594 | AE12: -17.202043 | AF12: -10.522378 | AG12: 18.473315 | AH12: -0.64729068 | AI12: 15.015903 | AJ12: 44.650443 | AK12: 3.1929969 | AL12: 23.72085 | AM12: 9.4512128
A13: INDUSTRY | B13: -0.60233732 | C13: 4.5995317 | D13: 16.225662 | E13: 7.9277803 | F13: 5.4100804 | G13: 2.8953153 | H13: 3.1727275 | I13: 7.983336 | J13: 9.0370626 | K13: 10.33215 | L13: 9.3709856 | M13: 7.4735698 | N13: 10.161699 | O13: 10.14047 | P13: 2.9512124 | Q13: -9.7908167 | R13: -2.2068791 | S13: -1.4690787 | T13: 2.1478318 | U13: 17.497705 | V13: -0.121214 | W13: 7.8245859 | X13: 5.5285218 | Y13: 7.0691761 | Z13: 12.288976 | AA13: -2.3754988 | AB13: 0.71107424 | AC13: 6.3594382 | AD13: 9.8953589 | AE13: 4.4842493 | AF13: 6.7230965 | AG13: 1.0980079 | AH13: 5.1231152 | AI13: 7.6514026 | AJ13: 7.3997957 | AK13: 7.5685941 | AL13: 5.9747366 | AM13: 12.257991
A14: Mining & quarrying | B14: -1.0176412 | C14: 27.163369 | D14: 42.921379 | E14: 66.601672 | F14: 13.006608 | G14: -18.740982 | H14: -9.5661008 | I14: -0.57039491 | J14: 24.298931 | K14: 20.557187 | L14: 34.417285 | M14: -4.1933679 | N14: 14.438809 | O14: 74.995995 | P14: 11.895181 | Q14: -17.180262 | R14: 41.884989 | S14: -1.1671934 | T14: -22.75651 | U14: 16.729088 | V14: -56.35978 | W14: 49.349266 | X14: 40.747538 | Y14: 85.318163 | Z14: 88.87278 | AA14: -51.808093 | AB14: -24.749961 | AC14: 52.798407 | AD14: 98.898205 | AE14: 96.165475 | AF14: 4.0587122 | AG14: -75.704656 | AH14: -8.5784039 | AI14: 9.7080505 | AJ14: -0.43884077 | AK14: 43.608635 | AL14: -10.422763 | AM14: 27.326816
A15: Manufacturing | B15: -5.7702586 | C15: -0.1731616 | D15: 19.811423 | E15: 2.5311368 | F15: 5.4633796 | G15: 4.7481879 | H15: 1.5302076 | I15: 7.0004646 | J15: 7.0445137 | K15: 9.3039472 | L15: 7.3653602 | M15: 7.0665881 | N15: 11.727523 | O15: 8.7620878 | P15: -1.0447553 | Q15: -14.187631 | R15: -3.6745882 | S15: -5.2621545 | T15: 2.2128016 | U15: 19.282766 | V15: -5.9504663 | W15: 6.4696502 | X15: 7.8324133 | Y15: 7.0007348 | Z15: 15.63553 | AA15: 1.340548 | AB15: -1.3522881 | AC15: -1.6233706 | AD15: 4.7048134 | AE15: -1.6219041 | AF15: 4.9918833 | AG15: 11.002473 | AH15: 6.180753 | AI15: 7.7516204 | AJ15: 5.2329828 | AK15: 3.4531782 | AL15: 4.7538875 | AM15: 8.9249589
A16: Electricity | B16: 6.141503 | C16: 9.4323279 | D16: 14.545286 | E16: 9.0047431 | F16: 10.700578 | G16: 7.7590666 | H16: 1.8638188 | I16: 1.6903329 | J16: -0.043102909 | K16: -0.19762631 | L16: 2.1198978 | M16: 8.1717764 | N16: 12.293811 | O16: 15.65624 | P16: 17.016475 | Q16: -0.82784518 | R16: 8.8043734 | S16: 8.9563825 | T16: 7.4383342 | U16: 22.418117 | V16: 5.076699 | W16: 3.2750999 | X16: 2.1326469 | Y16: 2.1648167 | Z16: 6.0942389 | AA16: 7.9300241 | AB16: 8.9793904 | AC16: 10.726104 | AD16: 11.911286 | AE16: 8.3203213 | AF16: 8.7335926 | AG16: 6.8706984 | AH16: 6.4461531 | AI16: 10.489541 | AJ16: 13.415091 | AK16: 16.929063 | AL16: 26.282647 | AM16: 10.799047
... A33: Activities of Households | B33: 2.6609965 | C33: 2.8320844 | D33: 2.924144 | E33: 2.936326 | F33: 2.8680716 | G33: 2.818773 | H33: 2.7883234 | I33: 2.776886 | J33: 2.7843704 | K33: 2.7881906 | L33: 2.7883971 | M33: 2.7846182 | N33: 2.776885 | O33: 2.7669055 | P33: 2.7550021 | Q33: 2.7409598 | R33: 2.7246889 | S33: 2.7139813 | T33: 2.7350163 | U33: 2.7613682 | V33: 2.767027 | W33: 2.7663441 | X33: 2.7596131 | Y33: 2.7465927 | Z33: 2.7271632 | AA33: 2.7142034 | AB33: 2.7339014 | AC33: 2.7598254 | AD33: 2.7659861 | AE33: 2.7659177 | AF33: 2.759914 | AG33: 2.7477363 | AH33: 2.729262 | AI33: 2.7158552 | AJ33: 2.7336983 | AK33: 2.7563359 | AL33: 2.7577825 | AM33: 2.0997339
A35: ADJUSTMENTS
