Workbook

Sheet USE OF DATA
C1: WHAT DO USERS WANT?
C2: MAIN USE OF DATA | D2: WHAT DATA SHOULD I USE? | E2: WORKSHEET
B3: 1 | C3: Policy Formulations | D3: The original unadjusted series and all components | E3: Original_VA
B4: 2 | C4: Macro-economic model building | D4: Could be Unadjusted, adjusted, trend-cycle or all components depending on the main purpose of the model | E4: Original_VA, Deseason_VA, Trend_VA
B5: 3 | C5: To determine what actually happened | D5: The original unadjusted series | E5: Original_VA
B6: 4 | C6: Analysis of the effect of particular events such as a strike | D6: The irregular component | E6: Deseason_VA and Trend_VA
B7: 5 | C7: Business Cycle analysis & detection of turning points | D7: Trend-cycle and irregular component | E7: Trend_VA
B8: 6 | C8: Short-term and medium term forecasting | D8: Original unadjusted series and all its components | E8: Original_VA
B9: 7 | C9: Long-term forecasting | D9: The trend cycle component | E9: Trend_VA
C12: Notes:
B13: a | C13: Original (Unadjusted) estimates have been benchmarked to the 2024/25 Annual GDP estimates (October release 2025) due to quarterly differences in source data for selected economic activities. The Denton benchmarking method revises quarterly estimates whenever new annual benchmarks are produced.
B14: b | C14: Therefore, there were no revisions in series because the benchmarks and input data have not been revised over the period. Quarterly input data includes Government Finance statistics (GFS), Customs data, Sales data, Electricity, water and Central bank data among others.
B15: c | C15: Seasonally adjusted data are subject to revisions as future data become available, even when the original data are not revised.
B16: d | C16: Seasonally adjusted and Trend-cycle estimates represent an analytical elaboration of the data designed to show the underlying movements that may be hidden by the seasonal variations.
B17: e | C17: Seasonally adjusted data is the sum of the Trend-cycle component and the Irregular component. When the Irregular component is strong, the Seasonally adjusted series may not present a smooth pattern.
B18: f | C18: Original (Unadjusted) data are useful in their own right. They show the actual economic events that have occurred and therefore Seasonally adjusted data should not replace the unadjusted data.
B19: h | C19: In terms of interpretation, original series consider year on year similar quarter changes due to seasonal effects while adjusted series consider quarter to quarter changes.

Sheet Summary
A2: TABLE 1: SUMMARY OF QGDP AT CONSTANT 2016/17 PRICES, BILLION SHILLINGS, 2016/17-2025/26
A3: Year | B3: 2007/08 | D3: 2008/09 | H3: 2009/10 | L3: 2010/11 | P3: 2011/12 | T3: 2012/13 | X3: 2013/14 | AB3: 2014/15 | AF3: 2015/16 | AJ3: 2016/17 | AN3: 2017/18 | AO3: 2017/18 | AR3: 2018/19 | AV3: 2019/20 | AZ3: 2020/21 | BD3: 2021/22 | BH3: 2022/23 | BL3: 2023/24 | BP3: 2024/25 | BT3: 2025/26
A4: Period | B4: Q3 | C4: Q4 | D4: Q1 | E4: Q2 | F4: Q3 | G4: Q4 | H4: Q1 | I4: Q2 | J4: Q3 | K4: Q4 | L4: Q1 | M4: Q2 | N4: Q3 | O4: Q4 | P4: Q1 | Q4: Q2 | R4: Q3 | S4: Q4 | T4: Q1 | U4: Q2 | V4: Q3 | W4: Q4 | X4: Q1 | Y4: Q2 | Z4: Q3 | AA4: Q4 | AB4: Q1 | AC4: Q2 | AD4: Q3 | AE4: Q4 | AF4: Q1 | AG4: Q2 | AH4: Q3 | AI4: Q4 | AJ4: Q1 | AK4: Q2 | AL4: Q3 | AM4: Q4 | AN4: Q1 | AO4: Q2 | AP4: Q3 | AQ4: Q4 | AR4: Q1 | AS4: Q2 | AT4: Q3 | AU4: Q4 | AV4: Q1 | AW4: Q2 | AX4: Q3 | AY4: Q4 | AZ4: Q1 | BA4: Q2 | BB4: Q3 | BC4: Q4 | BD4: Q1 | BE4: Q2 | BF4: Q3 | BG4: Q4 | BH4: Q1 | BI4: Q2 | BJ4: Q3 | BK4: Q4 | BL4: Q1 | BM4: Q2 | BN4: Q3 | BO4: Q4 | BP4: Q1 | BQ4: Q2 | BR4: Q3 | BS4: Q4 | BT4: Q1 | BU4: Q2 | BV4: Q3
A5: ORIGINAL ESTIMATES
A6: GDP at market prices | B6: 0 | C6: 0 | D6: 15766.403 | E6: 13927.632 | F6: 14022.629 | G6: 15998.234 | H6: 21078.882 | I6: 19122.748 | J6: 19608.559 | K6: 20695.656 | L6: 23193.526 | M6: 21456.643 | N6: 21240.165 | O6: 21202.324 | P6: 24535.906 | Q6: 21481.557 | R6: 21447.288 | S6: 22266.799 | T6: 26058 | U6: 22244.279 | V6: 21603.992 | W6: 21779.636 | X6: 25541.078 | Y6: 22459.838 | Z6: 23000.644 | AA6: 24675.991 | AB6: 26399.959 | AC6: 24996.444 | AD6: 24359.381 | AE6: 25617.315 | AF6: 28652.094 | AG6: 26475.799 | AH6: 24581.78 | AI6: 25513.407 | AJ6: 28577.247 | AK6: 26610.18 | AL6: 26240.178 | AM6: 27090.435 | AN6: 30772.237 | AO6: 28335.28 | AP6: 27653.331 | AQ6: 28598.087 | AR6: 32487.642 | AS6: 29958.631 | AT6: 29773.235 | AU6: 30567.095 | AV6: 34943.779 | AW6: 32466.458 | AX6: 30130.072 | AY6: 28870.102 | AZ6: 34802.923 | BA6: 32477.008 | BB6: 30975.024 | BC6: 32626.063 | BD6: 35622.436 | BE6: 34024.49 | BF6: 32716.662 | BG6: 34522.28 | BH6: 38746.737 | BI6: 35492.013 | BJ6: 33446.228 | BK6: 36506.452 | BL6: 41068.072 | BM6: 37544.31 | BN6: 35728.791 | BO6: 38581.884 | BP6: 43605.836 | BQ6: 39557.991 | BR6: 38727.987 | BS6: 40714.044 | BT6: 45718.884 | BU6: 42903.876 | BV6: 40970.227
A7: Agriculture, Forestry & Fishing | B7: 0 | C7: 0 | D7: 6507.5645 | E7: 4895.3189 | F7: 4423.9452 | G7: 5495.5749 | H7: 6875.3793 | I7: 5088.8484 | J7: 4451.0205 | K7: 5461.4456 | L7: 7007.5574 | M7: 5267.2451 | N7: 4769.982 | O7: 5440.697 | P7: 7871.5671 | Q7: 5290.0544 | R7: 4412.0205 | S7: 5051.4272 | T7: 8273.6224 | U7: 5294.8849 | V7: 4601.826 | W7: 4760.2442 | X7: 8300.5433 | Y7: 5337.7241 | Z7: 4567.2362 | AA7: 5324.0947 | AB7: 7787.9339 | AC7: 5886.4232 | AD7: 4831.2409 | AE7: 5566.2174 | AF7: 7919.4675 | AG7: 5919.3821 | AH7: 5302.9236 | AI7: 5632.0158 | AJ7: 8012.3898 | AK7: 6110.5575 | AL7: 5359.3298 | AM7: 5974.7915 | AN7: 8783.7536 | AO7: 6199.5724 | AP7: 5495.0897 | AQ7: 6096.0101 | AR7: 8974.6097 | AS7: 6448.4413 | AT7: 5935.2774 | AU7: 6628.7289 | AV7: 9517.4185 | AW7: 6941.2508 | AX7: 5858.4835 | AY7: 7019.6669 | AZ7: 10178.838 | BA7: 7480.0514 | BB7: 5874.7257 | BC7: 7070.5839 | BD7: 10624.95 | BE7: 7330.892 | BF7: 6120.4467 | BG7: 7804.9868 | BH7: 11088.263 | BI7: 8197.4364 | BJ7: 6452.1008 | BK7: 7589.8403 | BL7: 11715.27 | BM7: 8365.8311 | BN7: 6712.9791 | BO7: 8392.5624 | BP7: 12457.04 | BQ7: 9018.0558 | BR7: 7404.8569 | BS7: 8683.3829 | BT7: 12839.64 | BU7: 9809.0589 | BV7: 7563.1391
A8: Industry | B8: 0 | C8: 0 | D8: 1445.2869 | E8: 1434.6394 | F8: 1255.2376 | G8: 1878.6357 | H8: 4840.8447 | I8: 4784.2345 | J8: 5112.8414 | K8: 5061.3107 | L8: 5237.2134 | M8: 5571.0615 | N8: 5434.2561 | O8: 5453.5924 | P8: 5456.3648 | Q8: 5410.6693 | R8: 5788.7735 | S8: 5725.958 | T8: 5694.9937 | U8: 5636.6937 | V8: 5763.6888 | W8: 5400.4985 | X8: 5623.6031 | Y8: 5636.0437 | Z8: 6053.0605 | AA8: 6236.8023 | AB8: 6147.232 | AC8: 6295.2097 | AD8: 6521.915 | AE8: 6701.4139 | AF8: 6809.7306 | AG8: 6794.357 | AH8: 6285.5491 | AI8: 6548.1991 | AJ8: 6768.7131 | AK8: 7106.8656 | AL8: 7305.421 | AM8: 7067.3259 | AN8: 7134.9059 | AO8: 7312.6318 | AP8: 7537.2021 | AQ8: 7631.5343 | AR8: 7779.6918 | AS8: 8068.1838 | AT8: 8243.5123 | AU8: 8201.8824 | AV8: 8570.2406 | AW8: 8886.3356 | AX8: 8486.7958 | AY8: 7398.8511 | AZ8: 8381.1058 | BA8: 8755.7883 | BB8: 8669.0779 | BC8: 8693.4802 | BD8: 8370.9467 | BE8: 9440.8925 | BF8: 9148.3498 | BG8: 9308.0376 | BH8: 9399.6503 | BI8: 9216.6242 | BJ8: 9213.4013 | BK8: 9899.9765 | BL8: 10329.779 | BM8: 9629.9206 | BN8: 9832.8272 | BO8: 10008.679 | BP8: 10858.986 | BQ8: 10366.745 | BR8: 10560.436 | BS8: 10766.195 | BT8: 11507.782 | BU8: 11637.499 | BV8: 11186.239
A9: Services | B9: 0 | C9: 0 | D9: 6828.2243 | E9: 6685.4472 | F9: 7098.1846 | G9: 7433.0483 | H9: 8219.4414 | I9: 8170.5373 | J9: 8965.4911 | K9: 9084.0681 | L9: 9794.4675 | M9: 9376.4753 | N9: 9741.7914 | O9: 9084.9902 | P9: 9902.8734 | Q9: 9375.168 | R9: 9745.1126 | S9: 10034.585 | T9: 10681.667 | U9: 9953.8775 | V9: 9790.642 | W9: 10129.007 | X9: 10158.684 | Y9: 10046.633 | Z9: 10744.274 | AA9: 11519.17 | AB9: 10904.078 | AC9: 11159.16 | AD9: 11295.277 | AE9: 11541.693 | AF9: 12242.65 | AG9: 12024.127 | AH9: 11341.25 | AI9: 11523.07 | AJ9: 11937.718 | AK9: 11574.904 | AL9: 11626.766 | AM9: 12042.627 | AN9: 12862.303 | AO9: 12815.187 | AP9: 12685.299 | AQ9: 12837.368 | AR9: 13754.229 | AS9: 13368.754 | AT9: 13465.069 | AU9: 13600.746 | AV9: 14658.784 | AW9: 14367.919 | AX9: 13669.805 | AY9: 12849.732 | AZ9: 14119.436 | BA9: 14074.464 | BB9: 14391.411 | BC9: 14495.401 | BD9: 14539.216 | BE9: 14902.836 | BF9: 14962.971 | BG9: 14980.554 | BH9: 15799.82 | BI9: 15607.29 | BJ9: 15193.7 | BK9: 16317.733 | BL9: 16221.882 | BM9: 16906.179 | BN9: 16418.929 | BO9: 17379.216 | BP9: 17192.953 | BQ9: 17283.665 | BR9: 17847.735 | BS9: 18239.581 | BT9: 18170.905 | BU9: 18361.432 | BV9: 18894.608
A10: Adjustments
A11: Taxes on products | B11: 0 | C11: 0 | D11: 985.32762 | E11: 912.22689 | F11: 1245.2621 | G11: 1190.9755 | H11: 1143.2165 | I11: 1079.128 | J11: 1079.2056 | K11: 1088.832 | L11: 1154.2874 | M11: 1241.861 | N11: 1294.1352 | O11: 1223.0444 | P11: 1305.1011 | Q11: 1405.6656 | R11: 1501.3813 | S11: 1454.8283 | T11: 1407.7164 | U11: 1358.8227 | V11: 1447.8355 | W11: 1489.8856 | X11: 1458.2475 | Y11: 1439.4375 | Z11: 1636.0732 | AA11: 1595.9236 | AB11: 1560.7144 | AC11: 1655.6515 | AD11: 1710.9486 | AE11: 1807.9904 | AF11: 1680.2457 | AG11: 1737.9327 | AH11: 1652.0566 | AI11: 1810.1219 | AJ11: 1858.4261 | AK11: 1817.8528 | AL11: 1948.6611 | AM11: 2005.691 | AN11: 1991.2744 | AO11: 2007.8887 | AP11: 1935.7403 | AQ11: 2033.1747 | AR11: 1979.1119 | AS11: 2073.2514 | AT11: 2129.377 | AU11: 2135.7379 | AV11: 2197.3365 | AW11: 2270.9524 | AX11: 2114.9878 | AY11: 1601.8521 | AZ11: 2123.5437 | BA11: 2166.7043 | BB11: 2039.8093 | BC11: 2366.598 | BD11: 2087.3237 | BE11: 2349.8691 | BF11: 2484.895 | BG11: 2428.7012 | BH11: 2459.0041 | BI11: 2470.6617 | BJ11: 2587.0261 | BK11: 2698.9015 | BL11: 2801.1416 | BM11: 2642.3794 | BN11: 2764.0558 | BO11: 2801.4262 | BP11: 3096.8575 | BQ11: 2889.5255 | BR11: 2914.9594 | BS11: 3024.8849 | BT11: 3200.5564 | BU11: 3095.8858 | BV11: 3326.2404
A13: SEASONALLY ADJUSTED ESTIMATES
A14: GDP at market prices | B14: 0 | C14: 0 | D14: 0 | E14: 0 | F14: 0 | G14: 0 | H14: 19281.409 | I14: 19536.769 | J14: 20670.65 | K14: 21088.659 | L14: 21342.53 | M14: 21896.853 | N14: 22390.232 | O14: 21682.915 | P14: 22486.721 | Q14: 21911.014 | R14: 22517.31 | S14: 22741.164 | T14: 23670.651 | U14: 22632.373 | V14: 22653.884 | W14: 22266.491 | X14: 23206.646 | Y14: 22781.855 | Z14: 24142.298 | AA14: 25208.001 | AB14: 24323.405 | AC14: 25323.803 | AD14: 25570.867 | AE14: 26198.304 | AF14: 26581.324 | AG14: 26727.381 | AH14: 25866.214 | AI14: 26198.378 | AJ14: 26416.451 | AK14: 26812.127 | AL14: 27622.085 | AM14: 27889.914 | AN14: 28283.055 | AO14: 28554.154 | AP14: 29229.258 | AQ14: 29445.35 | AR14: 29941.017 | AS14: 30143.981 | AT14: 31566.283 | AU14: 31403.382 | AV14: 32277.506 | AW14: 32675.789 | AX14: 31950.55 | AY14: 29675.735 | AZ14: 31890.177 | BA14: 32666.766 | BB14: 32921.015 | BC14: 33306.169 | BD14: 32640.319 | BE14: 34251.442 | BF14: 35011.57 | BG14: 35145.427 | BH14: 35487.513 | BI14: 35824.548 | BJ14: 35816.891 | BK14: 36991.392 | BL14: 37471.979 | BM14: 37983.243 | BN14: 38376.532 | BO14: 39004.919 | BP14: 39841.908 | BQ14: 40048.472 | BR14: 41537.216 | BS14: 41152.31 | BT14: 41956.657 | BU14: 43451.338 | BV14: 43978.861
A15: Agriculture, Forestry & Fishing | B15: 0 | C15: 0 | D15: 0 | E15: 0 | F15: 0 | G15: 0 | H15: 5418.8793 | I15: 5379.0102 | J15: 5427.2084 | K15: 5738.8634 | L15: 5490.5743 | M15: 5532.3699 | N15: 5851.2593 | O15: 5835.9554 | P15: 6128.9977 | Q15: 5564.0629 | R15: 5419.9699 | S15: 5502.7141 | T15: 6154.724 | U15: 5509.1535 | V15: 5589.387 | W15: 5236.6888 | X15: 6195.7516 | Y15: 5535.5894 | Z15: 5643.2176 | AA15: 5850.6262 | AB15: 5919.8009 | AC15: 6130.1701 | AD15: 5947.1034 | AE15: 6098.914 | AF15: 6058.9851 | AG15: 6151.8418 | AH15: 6459.6385 | AI15: 6172.2801 | AJ15: 6113.4118 | AK15: 6365.2952 | AL15: 6582.8786 | AM15: 6545.6275 | AN15: 6624.1464 | AO15: 6533.1995 | AP15: 6887.5132 | AQ15: 6659.0806 | AR15: 6777.8345 | AS15: 6778.2824 | AT15: 7531.2265 | AU15: 7188.48 | AV15: 7180.5444 | AW15: 7289.088 | AX15: 7451.5711 | AY15: 7595.3947 | AZ15: 7565.5859 | BA15: 7818.2609 | BB15: 7524.9016 | BC15: 7643.6427 | BD15: 7912.3918 | BE15: 7634.5177 | BF15: 8038.7603 | BG15: 8456.0785 | BH15: 8143.4333 | BI15: 8514.0709 | BJ15: 8384.5547 | BK15: 8258.2818 | BL15: 8594.2364 | BM15: 8663.2015 | BN15: 8847.9762 | BO15: 9132.1583 | BP15: 9180.715 | BQ15: 9290.6771 | BR15: 9645.6266 | BS15: 9451.6369 | BT15: 9588.3204 | BU15: 10082.951 | BV15: 9947.8206
A16: Industry | B16: 0 | C16: 0 | D16: 0 | E16: 0 | F16: 0 | G16: 0 | H16: 4827.2019 | I16: 4837.9511 | J16: 5045.4056 | K16: 5080.7289 | L16: 5229.2668 | M16: 5654.5394 | N16: 5352.2274 | O16: 5467.2134 | P16: 5473.1409 | Q16: 5450.86 | R16: 5705.4645 | S16: 5710.1066 | T16: 5726.984 | U16: 5683.649 | V16: 5688.4441 | W16: 5393.8722 | X16: 5672.9448 | Y16: 5639.6677 | Z16: 5982.8773 | AA16: 6234.6007 | AB16: 6197.9643 | AC16: 6294.5185 | AD16: 6463.6108 | AE16: 6717.3836 | AF16: 6859.1499 | AG16: 6774.5135 | AH16: 6234.723 | AI16: 6603.0191 | AJ16: 6810.0732 | AK16: 7061.3088 | AL16: 7254.6058 | AM16: 7145.5964 | AN16: 7163.8099 | AO16: 7221.6637 | AP16: 7504.2004 | AQ16: 7734.8304 | AR16: 7795.0484 | AS16: 7955.7257 | AT16: 8235.0954 | AU16: 8306.1266 | AV16: 8565.2873 | AW16: 8788.3075 | AX16: 8519.1181 | AY16: 7489.7614 | AZ16: 8331.28 | BA16: 8659.1468 | BB16: 8751.579 | BC16: 8758.2813 | BD16: 8306.2219 | BE16: 9394.8316 | BF16: 9294.8048 | BG16: 9341.6653 | BH16: 9255.5267 | BI16: 9203.2318 | BJ16: 9383.2862 | BK16: 9914.2813 | BL16: 10037.899 | BM16: 9663.0934 | BN16: 10040.641 | BO16: 10001.922 | BP16: 10540.582 | BQ16: 10422.667 | BR16: 10795.036 | BS16: 10752.744 | BT16: 11182.707 | BU16: 11713.264 | BV16: 11447.732
A17: Services | B17: 0 | C17: 0 | D17: 0 | E17: 0 | F17: 0 | G17: 0 | H17: 7877.7986 | I17: 8234.0425 | J17: 9154.5646 | K17: 9167.8919 | L17: 9452.0913 | M17: 9458.9791 | N17: 9928.7761 | O17: 9149.6942 | P17: 9559.688 | Q17: 9479.3433 | R17: 9924.5286 | S17: 10075.781 | T17: 10355.4 | U17: 10071.589 | V17: 9954.1623 | W17: 10159.312 | X17: 9850.8713 | Y17: 10159.794 | Z17: 10894.89 | AA17: 11550.655 | AB17: 10614.952 | AC17: 11241.189 | AD17: 11449.704 | AE17: 11604.975 | AF17: 11954.947 | AG17: 12066.117 | AH17: 11510.078 | AI17: 11643.518 | AJ17: 11609.621 | AK17: 11580.561 | AL17: 11815.395 | AM17: 12220.121 | AN17: 12483.634 | AO17: 12810.474 | AP17: 12877.388 | AQ17: 13038.562 | AR17: 13373.209 | AS17: 13359.072 | AT17: 13646.548 | AU17: 13787.096 | AV17: 14323.205 | AW17: 14346.255 | AX17: 13846.436 | AY17: 12995.29 | AZ17: 13868.845 | BA17: 14031.988 | BB17: 14589.986 | BC17: 14537.278 | BD17: 14353.276 | BE17: 14863.887 | BF17: 15180.112 | BG17: 14912.123 | BH17: 15676.093 | BI17: 15605.013 | BJ17: 15449.46 | BK17: 16108.649 | BL17: 16111.275 | BM17: 16963.042 | BN17: 16708.756 | BO17: 17056.081 | BP17: 17116.937 | BQ17: 17379.74 | BR17: 18163.327 | BS17: 17910.008 | BT17: 18088.758 | BU17: 18487.026 | BV17: 19235.41
A18: Adjustments
A19: Taxes on products | B19: 0 | C19: 0 | D19: 0 | E19: 0 | F19: 0 | G19: 0 | H19: 1157.5288 | I19: 1085.765 | J19: 1043.4713 | K19: 1101.1745 | L19: 1170.5976 | M19: 1250.9646 | N19: 1257.9697 | O19: 1230.0517 | P19: 1324.8941 | Q19: 1416.7483 | R19: 1467.3473 | S19: 1452.5626 | T19: 1433.5429 | U19: 1367.9814 | V19: 1421.8904 | W19: 1476.618 | X19: 1487.0784 | Y19: 1446.8034 | Z19: 1621.3135 | AA19: 1572.1188 | AB19: 1590.6884 | AC19: 1657.9254 | AD19: 1710.4486 | AE19: 1777.0318 | AF19: 1708.2415 | AG19: 1734.9093 | AH19: 1661.7743 | AI19: 1779.5609 | AJ19: 1883.3454 | AK19: 1804.9623 | AL19: 1969.2047 | AM19: 1978.5694 | AN19: 2011.4652 | AO19: 1988.817 | AP19: 1960.1566 | AQ19: 2012.8766 | AR19: 1994.9247 | AS19: 2050.9008 | AT19: 2153.4128 | AU19: 2121.679 | AV19: 2208.4692 | AW19: 2252.1386 | AX19: 2133.4244 | AY19: 1595.2892 | AZ19: 2124.4659 | BA19: 2157.3696 | BB19: 2054.5485 | BC19: 2366.9671 | BD19: 2068.4292 | BE19: 2358.206 | BF19: 2497.8923 | BG19: 2435.561 | BH19: 2412.4606 | BI19: 2502.2327 | BJ19: 2599.5892 | BK19: 2710.1798 | BL19: 2728.5676 | BM19: 2693.9058 | BN19: 2779.159 | BO19: 2814.7584 | BP19: 3003.6741 | BQ19: 2955.3878 | BR19: 2933.2265 | BS19: 3037.9213 | BT19: 3096.8718 | BU19: 3168.0954 | BV19: 3347.8984
A21: TREND CYCLE ESTIMATES
A22: GDP at market prices | B22: 0 | C22: 0 | D22: 0 | E22: 0 | F22: 0 | G22: 0 | H22: 19321.521 | I22: 19646.987 | J22: 20838.39 | K22: 21122.126 | L22: 21418.024 | M22: 21679.12 | N22: 21679.066 | O22: 21729.735 | P22: 21900.113 | Q22: 22149.612 | R22: 22485.956 | S22: 22826.894 | T22: 22949.804 | U22: 22773.998 | V22: 22547.539 | W22: 22437.041 | X22: 22500.573 | Y22: 23012.92 | Z22: 23903.171 | AA22: 24489.84 | AB22: 24776.316 | AC22: 25114.087 | AD22: 25621.4 | AE22: 26114.928 | AF22: 26538.291 | AG22: 26545.612 | AH22: 26228.292 | AI22: 26164.867 | AJ22: 26459.003 | AK22: 26890.982 | AL22: 27386.001 | AM22: 27829.696 | AN22: 28157.98 | AO22: 28505.646 | AP22: 28964.892 | AQ22: 29471.224 | AR22: 29869.312 | AS22: 30328.589 | AT22: 30858.149 | AU22: 31484.421 | AV22: 32198.083 | AW22: 32489.962 | AX22: 32127.768 | AY22: 31925.614 | AZ22: 32151.054 | BA22: 32497.726 | BB22: 32852.132 | BC22: 32937.678 | BD22: 33205.301 | BE22: 34095.25 | BF22: 34842.847 | BG22: 35120.266 | BH22: 35413.009 | BI22: 35619.048 | BJ22: 36075.372 | BK22: 36783.201 | BL22: 37156.07 | BM22: 37436.947 | BN22: 38261.276 | BO22: 39229.273 | BP22: 39773.917 | BQ22: 40187.245 | BR22: 40669.909 | BS22: 41354.613 | BT22: 42247.595 | BU22: 43299.342 | BV22: 43749.461
A23: Agriculture, Forestry & Fishing | B23: 0 | C23: 0 | D23: 0 | E23: 0 | F23: 0 | G23: 0 | H23: 5456.4528 | I23: 5501.0784 | J23: 5622.9922 | K23: 5658.0279 | L23: 5604.7817 | M23: 5627.1605 | N23: 5712.0893 | O23: 5775.8788 | P23: 5770.1845 | Q23: 5670.4114 | R23: 5564.7467 | S23: 5524.5602 | T23: 5571.2425 | U23: 5579.444 | V23: 5522.0826 | W23: 5439.0315 | X23: 5493.6998 | Y23: 5593.7692 | Z23: 5679.3151 | AA23: 5849.0996 | AB23: 6013.0738 | AC23: 6026.2304 | AD23: 5992.5443 | AE23: 5989.9006 | AF23: 6028.0331 | AG23: 6154.1121 | AH23: 6248.4004 | AI23: 6239.5057 | AJ23: 6219.0738 | AK23: 6294.9721 | AL23: 6407.6262 | AM23: 6477.4047 | AN23: 6491.9933 | AO23: 6510.6556 | AP23: 6593.2904 | AQ23: 6679.911 | AR23: 6761.551 | AS23: 6852.1134 | AT23: 6975.3692 | AU23: 7095.5819 | AV23: 7180.5526 | AW23: 7249.5003 | AX23: 7355.6491 | AY23: 7495.235 | AZ23: 7590.5941 | BA23: 7587.172 | BB23: 7546.1287 | BC23: 7507.5132 | BD23: 7567.238 | BE23: 7797.3911 | BF23: 8061.116 | BG23: 8321.1141 | BH23: 8461.1524 | BI23: 8405.3815 | BJ23: 8326.4781 | BK23: 8334.9072 | BL23: 8409.8467 | BM23: 8569.3643 | BN23: 8758.1032 | BO23: 8937.1503 | BP23: 9086.2922 | BQ23: 9214.9188 | BR23: 9307.5554 | BS23: 9438.1408 | BT23: 9615.1067 | BU23: 9828.6601 | BV23: 9969.3845
A24: Industry | B24: 0 | C24: 0 | D24: 0 | E24: 0 | F24: 0 | G24: 0 | H24: 4762.3993 | I24: 4887.7176 | J24: 4991.0453 | K24: 5106.8593 | L24: 5235.9301 | M24: 5426.4245 | N24: 5512.3883 | O24: 5492.2461 | P24: 5449.0901 | Q24: 5507.1917 | R24: 5660.1333 | S24: 5728.8986 | T24: 5721.939 | U24: 5682.2286 | V24: 5604.6388 | W24: 5559.1196 | X24: 5569.6321 | Y24: 5692.5131 | Z24: 5967.2325 | AA24: 6174.2872 | AB24: 6236.1076 | AC24: 6289.1734 | AD24: 6478.9444 | AE24: 6711.3413 | AF24: 6848.7887 | AG24: 6738.781 | AH24: 6531.7343 | AI24: 6537.7427 | AJ24: 6789.8416 | AK24: 7076.0826 | AL24: 7201.3268 | AM24: 7181.2306 | AN24: 7144.0098 | AO24: 7255.6218 | AP24: 7492.5928 | AQ24: 7706.2398 | AR24: 7813.5987 | AS24: 7981.0773 | AT24: 8181.554 | AU24: 8353.3749 | AV24: 8582.9899 | AW24: 8706.9276 | AX24: 8615.8886 | AY24: 8575.2458 | AZ24: 8647.4598 | BA24: 8692.9233 | BB24: 8728.6795 | BC24: 8730.4523 | BD24: 8904.2465 | BE24: 9201.8962 | BF24: 9359.0755 | BG24: 9313.5986 | BH24: 9253.2018 | BI24: 9209.0996 | BJ24: 9459.294 | BK24: 9815.7914 | BL24: 9862.9134 | BM24: 9801.1103 | BN24: 9971.7823 | BO24: 10274.475 | BP24: 10441.688 | BQ24: 10556.827 | BR24: 10626.762 | BS24: 10832.183 | BT24: 11262.806 | BU24: 11552.607 | BV24: 11582.38
A25: Services | B25: 0 | C25: 0 | D25: 0 | E25: 0 | F25: 0 | G25: 0 | H25: 7943.1183 | I25: 8173.788 | J25: 9169.2212 | K25: 9262.4896 | L25: 9400.5815 | M25: 9383.5834 | N25: 9205.3745 | O25: 9210.7467 | P25: 9362.3681 | Q25: 9556.299 | R25: 9799.9901 | S25: 10113.276 | T25: 10238.375 | U25: 10123.442 | V25: 10004.329 | W25: 9970.7011 | X25: 9945.641 | Y25: 10193.99 | Z25: 10682.665 | AA25: 10885.594 | AB25: 10931.077 | AC25: 11147.524 | AD25: 11426.378 | AE25: 11664.576 | AF25: 11922.963 | AG25: 11949.407 | AH25: 11742.205 | AI25: 11612.695 | AJ25: 11587.203 | AK25: 11608.683 | AL25: 11826.031 | AM25: 12179.61 | AN25: 12519.955 | AO25: 12753.332 | AP25: 12901.271 | AQ25: 13093.978 | AR25: 13286.608 | AS25: 13433.235 | AT25: 13579.647 | AU25: 13883.356 | AV25: 14229.183 | AW25: 14314.426 | AX25: 13978.26 | AY25: 13707.136 | AZ25: 13763.144 | BA25: 14080.103 | BB25: 14429.394 | BC25: 14524.74 | BD25: 14485.152 | BE25: 14722.855 | BF25: 14959.208 | BG25: 15037.685 | BH25: 15273.056 | BI25: 15510.48 | BJ25: 15681.854 | BK25: 15932.939 | BL25: 16164.568 | BM25: 16347.416 | BN25: 16777.867 | BO25: 17166.186 | BP25: 17303.368 | BQ25: 17455.048 | BR25: 17780.576 | BS25: 18063.302 | BT25: 18275.622 | BU25: 18726.512 | BV25: 18869.73
A26: Adjustments
A27: Taxes on products | B27: 0 | C27: 0 | D27: 0 | E27: 0 | F27: 0 | G27: 0 | H27: 1159.5508 | I27: 1084.4034 | J27: 1055.1317 | K27: 1094.7496 | L27: 1176.7309 | M27: 1241.9519 | N27: 1249.2139 | O27: 1250.8631 | P27: 1318.4706 | Q27: 1415.7102 | R27: 1461.0856 | S27: 1460.159 | T27: 1418.2467 | U27: 1388.8833 | V27: 1416.4887 | W27: 1468.1885 | X27: 1491.6005 | Y27: 1532.6478 | Z27: 1573.9587 | AA27: 1580.8591 | AB27: 1596.0574 | AC27: 1651.1588 | AD27: 1723.5337 | AE27: 1749.1102 | AF27: 1738.5062 | AG27: 1703.3119 | AH27: 1705.9526 | AI27: 1774.9239 | AJ27: 1862.8842 | AK27: 1911.2443 | AL27: 1951.0168 | AM27: 1991.4507 | AN27: 2002.022 | AO27: 1986.037 | AP27: 1977.7382 | AQ27: 1991.0944 | AR27: 2007.5535 | AS27: 2062.1637 | AT27: 2121.5786 | AU27: 2152.1081 | AV27: 2205.3572 | AW27: 2219.1086 | AX27: 2177.9705 | AY27: 2147.9973 | AZ27: 2149.8566 | BA27: 2137.527 | BB27: 2147.9298 | BC27: 2174.9724 | BD27: 2248.6645 | BE27: 2373.1084 | BF27: 2463.4478 | BG27: 2447.8678 | BH27: 2425.5988 | BI27: 2494.0869 | BJ27: 2607.7459 | BK27: 2699.5631 | BL27: 2718.7423 | BM27: 2719.0569 | BN27: 2753.5235 | BO27: 2851.4611 | BP27: 2942.569 | BQ27: 2960.4515 | BR27: 2955.0151 | BS27: 3020.9878 | BT27: 3094.0604 | BU27: 3191.5626 | BV27: 3327.9668
A29: Source: Uganda Bureau of Statistics
A31: TABLE 2: SUMMARY OF QGDP AT CONSTANT 2016/17 PRICES, PERCENTAGE CHANGE, 2016/17-2025/26
A32: Year | B32: 2007/08 | D32: 2008/09 | H32: 2009/10 | L32: 2010/11 | P32: 2011/12 | T32: 2012/13 | X32: 2013/14 | AB32: 2014/15 | AF32: 2015/16 | AJ32: 2016/17 | AN32: 2017/18 | AO32: 2017/18 | AR32: 2018/19 | AV32: 2019/20 | AZ32: 2020/21 | BD32: 2021/22 | BH32: 2022/23 | BL32: 2023/24 | BP32: 2024/25 | BT32: 2025/26
A33: Period | B33: Q3 | C33: Q4 | D33: Q1 | E33: Q2 | F33: Q3 | G33: Q4 | H33: Q1 | I33: Q2 | J33: Q3 | K33: Q4 | L33: Q1 | M33: Q2 | N33: Q3 | O33: Q4 | P33: Q1 | Q33: Q2 | R33: Q3 | S33: Q4 | T33: Q1 | U33: Q2 | V33: Q3 | W33: Q4 | X33: Q1 | Y33: Q2 | Z33: Q3 | AA33: Q4 | AB33: Q1 | AC33: Q2 | AD33: Q3 | AE33: Q4 | AF33: Q1 | AG33: Q2 | AH33: Q3 | AI33: Q4 | AJ33: Q1 | AK33: Q2 | AL33: Q3 | AM33: Q4 | AN33: Q1 | AO33: Q2 | AP33: Q3 | AQ33: Q4 | AR33: Q1 | AS33: Q2 | AT33: Q3 | AU33: Q4 | AV33: Q1 | AW33: Q2 | AX33: Q3 | AY33: Q4 | AZ33: Q1 | BA33: Q2 | BB33: Q3 | BC33: Q4 | BD33: Q1 | BE33: Q2 | BF33: Q3 | BG33: Q4 | BH33: Q1 | BI33: Q2 | BJ33: Q3 | BK33: Q4 | BL33: Q1 | BM33: Q2 | BN33: Q3 | BO33: Q4 | BP33: Q1 | BQ33: Q2 | BR33: Q3 | BS33: Q4 | BT33: Q1 | BU33: Q2 | BV33: Q3
A34: ORIGINAL ESTIMATES
A35: GDP at market prices | C35: #DIV/0! | D35: #DIV/0! | E35: #VALUE! | F35: #DIV/0! | G35: #DIV/0! | H35: 33.69493 | I35: 37.300782 | J35: 39.835105 | K35: 29.362128 | L35: 10.032049 | M35: 12.204808 | N35: 8.3208874 | O35: 2.4481829 | P35: 5.7877391 | Q35: 0.11611492 | R35: 0.97514865 | S35: 5.0205571 | T35: 6.2035339 | U35: 3.5505873 | V35: 0.73064936 | W35: -2.187846 | X35: -1.9837358 | Y35: 0.96905631 | Z35: 6.4647828 | AA35: 13.298457 | AB35: 3.3627427 | AC35: 11.293963 | AD35: 5.90739 | AE35: 3.8147373 | AF35: 8.5308298 | AG35: 5.9182597 | AH35: 0.9129889 | AI35: -0.4056158 | AJ35: -0.26122599 | AK35: 0.50756396 | AL35: 6.7464548 | AM35: 6.1811727 | AN35: 7.6808998 | AO35: 6.4828574 | AP35: 5.3854549 | AQ35: 5.5652552 | AR35: 5.5745218 | AS35: 5.7290794 | AT35: 7.6659989 | AU35: 6.8851035 | AV35: 7.5602194 | AW35: 8.3709675 | AX35: 1.1985158 | AY35: -5.5516965 | AZ35: -0.40309239 | BA35: 0.032495737 | BB35: 2.804345 | BC35: 13.009861 | BD35: 2.354724 | BE35: 4.7648514 | BF35: 5.6227189 | BG35: 5.811971 | BH35: 8.7705981 | BI35: 4.3131379 | BJ35: 2.2299523 | BK35: 5.7475112 | BL35: 5.9910476 | BM35: 5.7824205 | BN35: 6.8245768 | BO35: 5.6851104 | BP35: 6.1794064 | BQ35: 5.3634777 | BR35: 8.394339 | BS35: 5.5263248 | BT35: 4.8457919 | BU35: 8.4581777 | BV35: 5.7897133
A36: Agriculture, Forestry & Fishing | C36: #DIV/0! | D36: #DIV/0! | E36: #VALUE! | F36: #DIV/0! | G36: #DIV/0! | H36: 5.6521111 | I36: 3.9533585 | J36: 0.61201628 | K36: -0.62103308 | L36: 1.9224835 | M36: 3.5056409 | N36: 7.1660324 | O36: -0.37990966 | P36: 12.329685 | Q36: 0.43304017 | R36: -7.504462 | S36: -7.1547783 | T36: 5.1076898 | U36: 0.091311944 | V36: 4.3020088 | W36: -5.7643713 | X36: 0.32538328 | Y36: 0.80906881 | Z36: -0.75165447 | AA36: 11.844991 | AB36: -6.1756126 | AC36: 10.279645 | AD36: 5.7804041 | AE36: 4.5476782 | AF36: 1.6889404 | AG36: 0.55991384 | AH36: 9.7631777 | AI36: 1.1821019 | AJ36: 1.1733408 | AK36: 3.2296506 | AL36: 1.0636812 | AM36: 6.0861995 | AN36: 9.6271373 | AO36: 1.4567401 | AP36: 2.5331515 | AQ36: 2.0288347 | AR36: 2.172831 | AS36: 4.0142917 | AT36: 8.010565 | AU36: 8.7388102 | AV36: 6.0482714 | AW36: 7.6423041 | AX36: -1.2938559 | AY36: 5.8976315 | AZ36: 6.9495696 | BA36: 7.7622984 | BB36: 0.27724211 | BC36: 0.72534795 | BD36: 4.382736 | BE36: -1.9940967 | BF36: 4.1826802 | BG36: 10.386736 | BH36: 4.3606145 | BI36: 11.82045 | BJ36: 5.4187897 | BK36: -2.7565253 | BL36: 5.654692 | BM36: 2.0542364 | BN36: 4.0433085 | BO36: 10.57627 | BP36: 6.331648 | BQ36: 7.796292 | BR36: 10.306569 | BS36: 3.4652179 | BT36: 3.0713611 | BU36: 8.7713266 | BV36: 2.1375446
A37: Industry | C37: #DIV/0! | D37: #DIV/0! | E37: #VALUE! | F37: #DIV/0! | G37: #DIV/0! | H37: 234.94004 | I37: 233.47993 | J37: 307.32062 | K37: 169.41417 | L37: 8.1880075 | M37: 16.446248 | N37: 6.28642 | O37: 7.7505946 | P37: 4.1845042 | Q37: -2.8790253 | R37: 6.5237527 | S37: 4.9942423 | T37: 4.3734039 | U37: 4.1773834 | V37: -0.43333384 | W37: -5.6839318 | X37: -1.2535665 | Y37: -0.011531378 | Z37: 5.0205984 | AA37: 15.485678 | AB37: 9.3112698 | AC37: 11.695546 | AD37: 7.7457436 | AE37: 7.4495173 | AF37: 10.777186 | AG37: 7.929001 | AH37: -3.6241797 | AI37: -2.2863059 | AJ37: -0.60233732 | AK37: 4.5995317 | AL37: 16.225662 | AM37: 7.9277803 | AN37: 5.4100804 | AO37: 2.8953153 | AP37: 3.1727275 | AQ37: 7.983336 | AR37: 9.0370626 | AS37: 10.33215 | AT37: 9.3709856 | AU37: 7.4735698 | AV37: 10.161699 | AW37: 10.14047 | AX37: 2.9512124 | AY37: -9.7908167 | AZ37: -2.2068791 | BA37: -1.4690787 | BB37: 2.1478318 | BC37: 17.497705 | BD37: -0.121214 | BE37: 7.8245859 | BF37: 5.5285218 | BG37: 7.0691761 | BH37: 12.288976 | BI37: -2.3754988 | BJ37: 0.71107424 | BK37: 6.3594382 | BL37: 9.8953589 | BM37: 4.4842493 | BN37: 6.7230965 | BO37: 1.0980079 | BP37: 5.1231152 | BQ37: 7.6514026 | BR37: 7.3997957 | BS37: 7.5685941 | BT37: 5.9747366 | BU37: 12.257991 | BV37: 5.9259193
A38: Services | C38: #DIV/0! | D38: #DIV/0! | E38: #VALUE! | F38: #DIV/0! | G38: #DIV/0! | H38: 20.374508 | I38: 22.213773 | J38: 26.306818 | K38: 22.211881 | L38: 19.162203 | M38: 14.759592 | N38: 8.6587584 | O38: 0.010149722 | P38: 1.1068078 | Q38: -0.01394228 | R38: 0.034092216 | S38: 10.452351 | T38: 7.8643215 | U38: 6.1727909 | V38: 0.46720325 | W38: 0.94096569 | X38: -4.8960841 | Y38: 0.93185245 | Z38: 9.7402359 | AA38: 13.724574 | AB38: 7.3375093 | AC38: 11.073626 | AD38: 5.1283416 | AE38: 0.19552666 | AF38: 12.275885 | AG38: 7.7511857 | AH38: 0.40701708 | AI38: -0.16135333 | AJ38: -2.4907341 | AK38: -3.736009 | AL38: 2.5175007 | AM38: 4.5088343 | AN38: 7.7450719 | AO38: 10.715277 | AP38: 9.1042744 | AQ38: 6.5993997 | AR38: 6.9344151 | AS38: 4.3196164 | AT38: 6.1470326 | AU38: 5.9465301 | AV38: 6.576558 | AW38: 7.4738828 | AX38: 1.5205013 | AY38: -5.5218535 | AZ38: -3.6793477 | BA38: -2.042432 | BB38: 5.2788271 | BC38: 12.807022 | BD38: 2.9730667 | BE38: 5.8856353 | BF38: 3.9715352 | BG38: 3.3469497 | BH38: 8.6703688 | BI38: 4.7269825 | BJ38: 1.5420013 | BK38: 8.9260995 | BL38: 2.6713069 | BM38: 8.3223194 | BN38: 8.0640636 | BO38: 6.505087 | BP38: 5.9861799 | BQ38: 2.2328288 | BR38: 8.7021833 | BS38: 4.9505378 | BT38: 5.6881024 | BU38: 6.2357551 | BV38: 5.8655812
A39: Adjustments
A40: Taxes on products | C40: #DIV/0! | D40: #DIV/0! | E40: #VALUE! | F40: #DIV/0! | G40: #DIV/0! | H40: 16.024002 | I40: 18.296005 | J40: -13.335066 | K40: -8.5764566 | L40: 0.96839961 | M40: 15.080046 | N40: 19.91554 | O40: 12.326273 | P40: 13.06552 | Q40: 13.190256 | R40: 16.01425 | S40: 18.951389 | T40: 7.8626362 | U40: -3.3324373 | V40: -3.5664363 | W40: 2.4097213 | X40: 3.5895789 | Y40: 5.9326991 | Z40: 13.001319 | AA40: 7.1171898 | AB40: 7.0267161 | AC40: 15.020728 | AD40: 4.576532 | AE40: 13.288031 | AF40: 7.6587553 | AG40: 4.9697145 | AH40: -3.4420658 | AI40: 0.11789288 | AJ40: 10.604422 | AK40: 4.5985732 | AL40: 17.953651 | AM40: 10.804192 | AN40: 7.14843 | AO40: 10.453864 | AP40: -0.66306097 | AQ40: 1.3702884 | AR40: -0.61078727 | AS40: 3.2552983 | AT40: 10.00324 | AU40: 5.0444829 | AV40: 11.026391 | AW40: 9.535794 | AX40: -0.67574802 | AY40: -24.997721 | AZ40: -3.3582876 | BA40: -4.5905031 | BB40: -3.5545582 | BC40: 47.741356 | BD40: -1.7056382 | BE40: 8.453615 | BF40: 21.819967 | BG40: 2.6241571 | BH40: 17.806552 | BI40: 5.1403958 | BJ40: 4.1100754 | BK40: 11.125298 | BL40: 13.913662 | BM40: 6.9502737 | BN40: 6.8429801 | BO40: 3.7987589 | BP40: 10.556979 | BQ40: 9.3531628 | BR40: 5.4594994 | BS40: 7.9766044 | BT40: 3.3485178 | BU40: 7.1416697 | BV40: 14.109321
A42: SEASONALLY ADJUSTED ESTIMATES
A43: GDP at market prices | C43: #DIV/0! | D43: #DIV/0! | E43: #DIV/0! | F43: #DIV/0! | G43: #DIV/0! | H43: #DIV/0! | I43: 1.3243858 | J43: 5.8038312 | K43: 2.0222336 | L43: 1.2038283 | M43: 2.5972695 | N43: 2.2531977 | O43: -3.1590458 | P43: 3.7070942 | Q43: -2.5602057 | R43: 2.7670824 | S43: 0.99414176 | T43: 4.087245 | U43: -4.3863552 | V43: 0.095047173 | W43: -1.7100512 | X43: 4.2222874 | Y43: -1.8304732 | Z43: 5.9716097 | AA43: 4.4142547 | AB43: -3.5091846 | AC43: 4.1129018 | AD43: 0.97561912 | AE43: 2.4537186 | AF43: 1.4620019 | AG43: 0.5494736 | AH43: -3.2220419 | AI43: 1.2841621 | AJ43: 0.83239308 | AK43: 1.4978379 | AL43: 3.0208624 | AM43: 0.96962078 | AN43: 1.4096175 | AO43: 0.95852186 | AP43: 2.3642921 | AQ43: 0.73929905 | AR43: 1.6833459 | AS43: 0.67788171 | AT43: 4.7183604 | AU43: -0.51606042 | AV43: 2.7835341 | AW43: 1.233933 | AX43: -2.2194993 | AY43: -7.1197978 | AZ43: 7.4621281 | BA43: 2.4351986 | BB43: 0.77831284 | BC43: 1.1699338 | BD43: -1.9991802 | BE43: 4.9359917 | BF43: 2.2192565 | BG43: 0.3823237 | BH43: 0.97334385 | BI43: 0.94972824 | BJ43: -0.021375292 | BK43: 3.2791842 | BL43: 1.2991837 | BM43: 1.3643908 | BN43: 1.0354276 | BO43: 1.6374267 | BP43: 2.1458546 | BQ43: 0.51845912 | BR43: 3.7173548 | BS43: -0.92665304 | BT43: 1.954561 | BU43: 3.5624392 | BV43: 1.2140564
A44: Agriculture, Forestry & Fishing | C44: #DIV/0! | D44: #DIV/0! | E44: #DIV/0! | F44: #DIV/0! | G44: #DIV/0! | H44: #DIV/0! | I44: -0.73574461 | J44: 0.89604237 | K44: 5.7424551 | L44: -4.326451 | M44: 0.76122511 | N44: 5.764064 | O44: -0.26154903 | P44: 5.0213261 | Q44: -9.2174101 | R44: -2.5897083 | S44: 1.5266548 | T44: 11.848879 | U44: -10.489025 | V44: 1.4563684 | W44: -6.3101413 | X44: 18.314298 | Y44: -10.655078 | Z44: 1.9442937 | AA44: 3.6753608 | AB44: 1.1823483 | AC44: 3.553653 | AD44: -2.9863239 | AE44: 2.5526819 | AF44: -0.65468886 | AG44: 1.5325457 | AH44: 5.0033258 | AI44: -4.4485212 | AJ44: -0.95375315 | AK44: 4.1201765 | AL44: 3.4182772 | AM44: -0.56587876 | AN44: 1.1995622 | AO44: -1.3729598 | AP44: 5.4232797 | AQ44: -3.3166197 | AR44: 1.7833388 | AS44: 0.0066075237 | AT44: 11.108185 | AU44: -4.5510055 | AV44: -0.11039391 | AW44: 1.5116347 | AX44: 2.229128 | AY44: 1.9301113 | AZ44: -0.39245801 | BA44: 3.3397942 | BB44: -3.7522327 | BC44: 1.5779749 | BD44: 3.5159819 | BE44: -3.5118845 | BF44: 5.2949332 | BG44: 5.1913246 | BH44: -3.6972832 | BI44: 4.5513684 | BJ44: -1.5212018 | BK44: -1.5060182 | BL44: 4.0680935 | BM44: 0.80245658 | BN44: 2.1328688 | BO44: 3.2118319 | BP44: 0.53171097 | BQ44: 1.1977514 | BR44: 3.8204911 | BS44: -2.0111679 | BT44: 1.4461358 | BU44: 5.158682 | BV44: -1.3401906
A45: Industry | C45: #DIV/0! | D45: #DIV/0! | E45: #DIV/0! | F45: #DIV/0! | G45: #DIV/0! | H45: #DIV/0! | I45: 0.22267979 | J45: 4.2880642 | K45: 0.70010748 | L45: 2.9235553 | M45: 8.1325471 | N45: -5.3463594 | O45: 2.1483782 | P45: 0.10841875 | Q45: -0.40709601 | R45: 4.6709058 | S45: 0.081361935 | T45: 0.2955701 | U45: -0.75668137 | V45: 0.084367622 | W45: -5.1784273 | X45: 5.1738829 | Y45: -0.58659302 | Z45: 6.0856356 | AA45: 4.2073961 | AB45: -0.58762935 | AC45: 1.5578362 | AD45: 2.686343 | AE45: 3.9261773 | AF45: 2.1104392 | AG45: -1.2339204 | AH45: -7.9679594 | AI45: 5.907176 | AJ45: 3.1357491 | AK45: 3.6891767 | AL45: 2.7374102 | AM45: -1.5026234 | AN45: 0.25489153 | AO45: 0.80758429 | AP45: 3.9123497 | AQ45: 3.0733444 | AR45: 0.77853025 | AS45: 2.0612748 | AT45: 3.5115546 | AU45: 0.86254315 | AV45: 3.1201146 | AW45: 2.6037675 | AX45: -3.0630401 | AY45: -12.082902 | AZ45: 11.235586 | BA45: 3.9353722 | BB45: 1.0674508 | BC45: 0.076583894 | BD45: -5.1615079 | BE45: 13.105955 | BF45: -1.0647003 | BG45: 0.50415779 | BH45: -0.92209023 | BI45: -0.56501245 | BJ45: 1.9564256 | BK45: 5.6589466 | BL45: 1.2468676 | BM45: -3.7339074 | BN45: 3.9071072 | BO45: -0.38562384 | BP45: 5.3855654 | BQ45: -1.118672 | BR45: 3.5726787 | BS45: -0.39176552 | BT45: 3.9986269 | BU45: 4.7444492 | BV45: -2.266936
A46: Services | C46: #DIV/0! | D46: #DIV/0! | E46: #DIV/0! | F46: #DIV/0! | G46: #DIV/0! | H46: #DIV/0! | I46: 4.522126 | J46: 11.179468 | K46: 0.14558072 | L46: 3.0999426 | M46: 0.072870878 | N46: 4.9666771 | O46: -7.8467062 | P46: 4.4809559 | Q46: -0.84045252 | R46: 4.6963727 | S46: 1.5240258 | T46: 2.7751642 | U46: -2.7407123 | V46: -1.165917 | W46: 2.060943 | X46: -3.0360385 | Y46: 3.1359953 | Z46: 8.5 | AA46: 6.0190173 | AB46: -8.1008687 | AC46: 5.8995797 | AD46: 1.8549196 | AE46: 1.3561089 | AF46: 3.0157122 | AG46: 0.92990201 | AH46: -4.608265 | AI46: 1.1593299 | AJ46: -0.29112186 | AK46: -0.25031112 | AL46: 2.0278347 | AM46: 3.4254062 | AN46: 2.1563854 | AO46: 2.6181518 | AP46: 0.52233515 | AQ46: 1.2516072 | AR46: 2.5665951 | AS46: -0.1057089 | AT46: 2.1519144 | AU46: 1.0299163 | AV46: 3.8884808 | AW46: 0.16092571 | AX46: -3.4839647 | AY46: -6.1470419 | AZ46: 6.7220879 | BA46: 1.1763311 | BB46: 3.9766139 | BC46: -0.36126091 | BD46: -1.2657258 | BE46: 3.5574523 | BF46: 2.1274735 | BG46: -1.7654006 | BH46: 5.1231474 | BI46: -0.45342903 | BJ46: -0.99680952 | BK46: 4.266744 | BL46: 0.016300497 | BM46: 5.286775 | BN46: -1.4990608 | BO46: 2.0787011 | BP46: 0.35680224 | BQ46: 1.5353372 | BR46: 4.5086241 | BS46: -1.3946764 | BT46: 0.99804961 | BU46: 2.2017437 | BV46: 4.0481563
...

Sheet Summary IPD
X2: Table 3: Summary of QGDP at constant 2009/10 prices, IMPLICIT PRICE DEFLATORS, 2013/14-2017/18
B3: 2007/08 | D3: 2008/09 | H3: 2009/10 | L3: 2010/11 | P3: 2011/12 | U3: 2012/13 | X3: 2013/14 | AB3: 2014/15 | AF3: 2015/16 | AJ3: 2016/17 | AN3: 2017/18
A4: ACTIVITY | B4: Q3 | C4: Q4 | D4: Q1 | E4: Q2 | F4: Q3 | G4: Q4 | H4: Q1 | I4: Q2 | J4: Q3 | K4: Q4 | L4: Q1 | M4: Q2 | N4: Q3 | O4: Q4 | P4: Q1 | Q4: Q2 | R4: Q3 | S4: Q4 | T4: Q1 | U4: Q2 | V4: Q3 | W4: Q4 | X4: Q1 | Y4: Q2 | Z4: Q3 | AA4: Q4 | AB4: Q1 | AC4: Q2 | AD4: Q3 | AE4: Q4 | AF4: Q1 | AG4: Q2 | AH4: Q3 | AI4: Q4 | AJ4: Q1 | AK4: Q2 | AL4: Q3 | AM4: Q4 | AN4: Q1 | AO4: Q2 | AP4: Q3 | AQ4: Q4
A5: ORIGINAL ESTIMATES
A6: GDP at market prices | B6: =#REF!/Summary!B6*100 -> #REF! | C6: =#REF!/Summary!C6*100 -> #REF! | D6: =#REF!/Summary!D6*100 -> #REF! | E6: =#REF!/Summary!E6*100 -> #REF! | F6: =#REF!/Summary!F6*100 -> #REF! | G6: =#REF!/Summary!G6*100 -> #REF! | H6: =#REF!/Summary!H6*100 -> #REF! | I6: =#REF!/Summary!I6*100 -> #REF! | ... AQ6: =#REF!/Summary!AQ6*100 -> #REF!
A7: Agriculture, Forestry & Fishing | B7: =#REF!/Summary!B7*100 -> #REF! | C7: =#REF!/Summary!C7*100 -> #REF! | D7: =#REF!/Summary!D7*100 -> #REF! | E7: =#REF!/Summary!E7*100 -> #REF! | F7: =#REF!/Summary!F7*100 -> #REF! | G7: =#REF!/Summary!G7*100 -> #REF! | H7: =#REF!/Summary!H7*100 -> #REF! | I7: =#REF!/Summary!I7*100 -> #REF! | ... AQ7: =#REF!/Summary!AQ7*100 -> #REF!
A8: Industry | B8: =#REF!/Summary!B8*100 -> #REF! | C8: =#REF!/Summary!C8*100 -> #REF! | D8: =#REF!/Summary!D8*100 -> #REF! | E8: =#REF!/Summary!E8*100 -> #REF! | F8: =#REF!/Summary!F8*100 -> #REF! | G8: =#REF!/Summary!G8*100 -> #REF! | H8: =#REF!/Summary!H8*100 -> #REF! | I8: =#REF!/Summary!I8*100 -> #REF! | ... AQ8: =#REF!/Summary!AQ8*100 -> #REF!
A9: Services | B9: =#REF!/Summary!B9*100 -> #REF! | C9: =#REF!/Summary!C9*100 -> #REF! | D9: =#REF!/Summary!D9*100 -> #REF! | E9: =#REF!/Summary!E9*100 -> #REF! | F9: =#REF!/Summary!F9*100 -> #REF! | G9: =#REF!/Summary!G9*100 -> #REF! | H9: =#REF!/Summary!H9*100 -> #REF! | I9: =#REF!/Summary!I9*100 -> #REF! | ... AQ9: =#REF!/Summary!AQ9*100 -> #REF!
A10: Adjustments
A11: Taxes on products | B11: =#REF!/Summary!B11*100 -> #REF! | C11: =#REF!/Summary!C11*100 -> #REF! | D11: =#REF!/Summary!D11*100 -> #REF! | E11: =#REF!/Summary!E11*100 -> #REF! | F11: =#REF!/Summary!F11*100 -> #REF! | G11: =#REF!/Summary!G11*100 -> #REF! | H11: =#REF!/Summary!H11*100 -> #REF! | I11: =#REF!/Summary!I11*100 -> #REF! | ... AQ11: =#REF!/Summary!AQ11*100 -> #REF!
A13: SEASONALLY ADJUSTED ESTIMATES
A14: GDP at market prices | B14: =#REF!/Summary!B14*100 -> #REF! | C14: =#REF!/Summary!C14*100 -> #REF! | D14: =#REF!/Summary!D14*100 -> #REF! | E14: =#REF!/Summary!E14*100 -> #REF! | F14: =#REF!/Summary!F14*100 -> #REF! | G14: =#REF!/Summary!G14*100 -> #REF! | H14: =#REF!/Summary!H14*100 -> #REF! | I14: =#REF!/Summary!I14*100 -> #REF! | ... AQ14: =#REF!/Summary!AQ14*100 -> #REF!
A15: Agriculture, Forestry & Fishing | B15: =#REF!/Summary!B15*100 -> #REF! | C15: =#REF!/Summary!C15*100 -> #REF! | D15: =#REF!/Summary!D15*100 -> #REF! | E15: =#REF!/Summary!E15*100 -> #REF! | F15: =#REF!/Summary!F15*100 -> #REF! | G15: =#REF!/Summary!G15*100 -> #REF! | H15: =#REF!/Summary!H15*100 -> #REF! | I15: =#REF!/Summary!I15*100 -> #REF! | ... AQ15: =#REF!/Summary!AQ15*100 -> #REF!
A16: Industry | B16: =#REF!/Summary!B16*100 -> #REF! | C16: =#REF!/Summary!C16*100 -> #REF! | D16: =#REF!/Summary!D16*100 -> #REF! | E16: =#REF!/Summary!E16*100 -> #REF! | F16: =#REF!/Summary!F16*100 -> #REF! | G16: =#REF!/Summary!G16*100 -> #REF! | H16: =#REF!/Summary!H16*100 -> #REF! | I16: =#REF!/Summary!I16*100 -> #REF! | ... AQ16: =#REF!/Summary!AQ16*100 -> #REF!
A17: Services | B17: =#REF!/Summary!B17*100 -> #REF! | C17: =#REF!/Summary!C17*100 -> #REF! | D17: =#REF!/Summary!D17*100 -> #REF! | E17: =#REF!/Summary!E17*100 -> #REF! | F17: =#REF!/Summary!F17*100 -> #REF! | G17: =#REF!/Summary!G17*100 -> #REF! | H17: =#REF!/Summary!H17*100 -> #REF! | I17: =#REF!/Summary!I17*100 -> #REF! | ... AQ17: =#REF!/Summary!AQ17*100 -> #REF!
A18: Adjustments
A19: Taxes on products | B19: =#REF!/Summary!B19*100 -> #REF! | C19: =#REF!/Summary!C19*100 -> #REF! | D19: =#REF!/Summary!D19*100 -> #REF! | E19: =#REF!/Summary!E19*100 -> #REF! | F19: =#REF!/Summary!F19*100 -> #REF! | G19: =#REF!/Summary!G19*100 -> #REF! | H19: =#REF!/Summary!H19*100 -> #REF! | I19: =#REF!/Summary!I19*100 -> #REF! | ... AQ19: =#REF!/Summary!AQ19*100 -> #REF!
A21: TREND CYCLE ESTIMATES
A22: GDP at market prices | B22: =#REF!/Summary!B22*100 -> #REF! | C22: =#REF!/Summary!C22*100 -> #REF! | D22: =#REF!/Summary!D22*100 -> #REF! | E22: =#REF!/Summary!E22*100 -> #REF! | F22: =#REF!/Summary!F22*100 -> #REF! | G22: =#REF!/Summary!G22*100 -> #REF! | H22: =#REF!/Summary!H22*100 -> #REF! | I22: =#REF!/Summary!I22*100 -> #REF! | ... AQ22: =#REF!/Summary!AQ22*100 -> #REF!
A23: Agriculture, Forestry & Fishing | B23: =#REF!/Summary!B23*100 -> #REF! | C23: =#REF!/Summary!C23*100 -> #REF! | D23: =#REF!/Summary!D23*100 -> #REF! | E23: =#REF!/Summary!E23*100 -> #REF! | F23: =#REF!/Summary!F23*100 -> #REF! | G23: =#REF!/Summary!G23*100 -> #REF! | H23: =#REF!/Summary!H23*100 -> #REF! | I23: =#REF!/Summary!I23*100 -> #REF! | ... AQ23: =#REF!/Summary!AQ23*100 -> #REF!
A24: Industry | B24: =#REF!/Summary!B24*100 -> #REF! | C24: =#REF!/Summary!C24*100 -> #REF! | D24: =#REF!/Summary!D24*100 -> #REF! | E24: =#REF!/Summary!E24*100 -> #REF! | F24: =#REF!/Summary!F24*100 -> #REF! | G24: =#REF!/Summary!G24*100 -> #REF! | H24: =#REF!/Summary!H24*100 -> #REF! | I24: =#REF!/Summary!I24*100 -> #REF! | ... AQ24: =#REF!/Summary!AQ24*100 -> #REF!
A25: Services | B25: =#REF!/Summary!B25*100 -> #REF! | C25: =#REF!/Summary!C25*100 -> #REF! | D25: =#REF!/Summary!D25*100 -> #REF! | E25: =#REF!/Summary!E25*100 -> #REF! | F25: =#REF!/Summary!F25*100 -> #REF! | G25: =#REF!/Summary!G25*100 -> #REF! | H25: =#REF!/Summary!H25*100 -> #REF! | I25: =#REF!/Summary!I25*100 -> #REF! | ... AQ25: =#REF!/Summary!AQ25*100 -> #REF!
A26: Adjustments
A27: Taxes on products | B27: =#REF!/Summary!B27*100 -> #REF! | C27: =#REF!/Summary!C27*100 -> #REF! | D27: =#REF!/Summary!D27*100 -> #REF! | E27: =#REF!/Summary!E27*100 -> #REF! | F27: =#REF!/Summary!F27*100 -> #REF! | G27: =#REF!/Summary!G27*100 -> #REF! | H27: =#REF!/Summary!H27*100 -> #REF! | I27: =#REF!/Summary!I27*100 -> #REF! | ... AQ27: =#REF!/Summary!AQ27*100 -> #REF!
A28: Uganda Bureau of Statistics
X30: Table 4: Summary of QGDP at constant prices, PERCENTAGE SHARE, 2013/14-2017/18
B31: 2007/08 | D31: 2008/09 | H31: 2009/10 | L31: 2010/11 | P31: 2011/12 | U31: 2012/13 | X31: 2013/14 | AB31: 2014/15 | AF31: 2015/16 | AJ31: 2016/17 | AN31: 2017/18
A32: ACTIVITY | B32: Q3 | C32: Q4 | D32: Q1 | E32: Q2 | F32: Q3 | G32: Q4 | H32: Q1 | I32: Q2 | J32: Q3 | K32: Q4 | L32: Q1 | M32: Q2 | N32: Q3 | O32: Q4 | P32: Q1 | Q32: Q2 | R32: Q3 | S32: Q4 | T32: Q1 | U32: Q2 | V32: Q3 | W32: Q4 | X32: Q1 | Y32: Q2 | Z32: Q3 | AA32: Q4 | AB32: Q1 | AC32: Q2 | AD32: Q3 | AE32: Q4 | AF32: Q1 | AG32: Q2 | AH32: Q3 | AI32: Q4 | AJ32: Q1 | AK32: Q2 | AL32: Q3 | AM32: Q4 | AN32: Q1 | AO32: Q2 | AP32: Q3 | AQ32: Q4
A33: ORIGINAL ESTIMATES
A34: GDP at market prices | B34: =Summary!B6/Summary!B$6*100 -> #DIV/0! | C34: =Summary!C6/Summary!C$6*100 -> #DIV/0! | D34: =Summary!D6/Summary!D$6*100 -> 100 | E34: =Summary!E6/Summary!E$6*100 -> 100 | F34: =Summary!F6/Summary!F$6*100 -> 100 | G34: =Summary!G6/Summary!G$6*100 -> 100 | H34: =Summary!H6/Summary!H$6*100 -> 100 | I34: =Summary!I6/Summary!I$6*100 -> 100 | J34: =Summary!J6/Summary!J$6*100 -> 100 | K34: =SUM(K35:K39) -> 100 | L34: =SUM(L35:L39) -> 100 | M34: =SUM(M35:M39) -> 100 | N34: =SUM(N35:N39) -> 100 | O34: =SUM(O35:O39) -> 100 | P34: =SUM(P35:P39) -> 100 | Q34: =SUM(Q35:Q39) -> 100 | R34: =SUM(R35:R39) -> 100 | ... AQ34: =SUM(AQ35:AQ39) -> 100
A35: Agriculture, Forestry & Fishing | B35: =Summary!B7/Summary!B$6*100 -> #DIV/0! | C35: =Summary!C7/Summary!C$6*100 -> #DIV/0! | D35: =Summary!D7/Summary!D$6*100 -> 41.274883 | E35: =Summary!E7/Summary!E$6*100 -> 35.148249 | F35: =Summary!F7/Summary!F$6*100 -> 31.548614 | G35: =Summary!G7/Summary!G$6*100 -> 34.351134 | H35: =Summary!H7/Summary!H$6*100 -> 32.617381 | I35: =Summary!I7/Summary!I$6*100 -> 26.611491 | ... AQ35: =Summary!AQ7/Summary!AQ$6*100 -> 21.316147
A36: Industry | B36: =Summary!B8/Summary!B$6*100 -> #DIV/0! | C36: =Summary!C8/Summary!C$6*100 -> #DIV/0! | D36: =Summary!D8/Summary!D$6*100 -> 9.1668778 | E36: =Summary!E8/Summary!E$6*100 -> 10.30067 | F36: =Summary!F8/Summary!F$6*100 -> 8.9515134 | G36: =Summary!G8/Summary!G$6*100 -> 11.742769 | H36: =Summary!H8/Summary!H$6*100 -> 22.965377 | I36: =Summary!I8/Summary!I$6*100 -> 25.018551 | ... AQ36: =Summary!AQ8/Summary!AQ$6*100 -> 26.685471
A37: Services | B37: =Summary!B9/Summary!B$6*100 -> #DIV/0! | C37: =Summary!C9/Summary!C$6*100 -> #DIV/0! | D37: =Summary!D9/Summary!D$6*100 -> 43.3087 | E37: =Summary!E9/Summary!E$6*100 -> 48.001319 | F37: =Summary!F9/Summary!F$6*100 -> 50.619498 | G37: =Summary!G9/Summary!G$6*100 -> 46.461679 | H37: =Summary!H9/Summary!H$6*100 -> 38.993726 | I37: =Summary!I9/Summary!I$6*100 -> 42.726795 | ... AQ37: =Summary!AQ9/Summary!AQ$6*100 -> 44.888904
A38: Adjustments
A39: Taxes on products | B39: =Summary!B11/Summary!B$6*100 -> #DIV/0! | C39: =Summary!C11/Summary!C$6*100 -> #DIV/0! | D39: =Summary!D11/Summary!D$6*100 -> 6.2495396 | E39: =Summary!E11/Summary!E$6*100 -> 6.5497628 | F39: =Summary!F11/Summary!F$6*100 -> 8.8803753 | G39: =Summary!G11/Summary!G$6*100 -> 7.4444184 | H39: =Summary!H11/Summary!H$6*100 -> 5.423516 | I39: =Summary!I11/Summary!I$6*100 -> 5.6431636 | ... AQ39: =Summary!AQ11/Summary!AQ$6*100 -> 7.1094781
A41: SEASONALLY ADJUSTED ESTIMATES
A42: GDP at market prices | B42: =Summary!B14/Summary!B$14*100 -> #DIV/0! | C42: =Summary!C14/Summary!C$14*100 -> #DIV/0! | D42: =Summary!D14/Summary!D$14*100 -> #DIV/0! | E42: =Summary!E14/Summary!E$14*100 -> #DIV/0! | F42: =Summary!F14/Summary!F$14*100 -> #DIV/0! | G42: =Summary!G14/Summary!G$14*100 -> #DIV/0! | H42: =Summary!H14/Summary!H$14*100 -> 100 | I42: =Summary!I14/Summary!I$14*100 -> 100 | J42: =Summary!J14/Summary!J$14*100 -> 100 | K42: =SUM(K43:K47) -> 100 | L42: =SUM(L43:L47) -> 100 | M42: =SUM(M43:M47) -> 100 | N42: =SUM(N43:N47) -> 100 | O42: =SUM(O43:O47) -> 100 | P42: =SUM(P43:P47) -> 100 | Q42: =SUM(Q43:Q47) -> 100 | R42: =SUM(R43:R47) -> 100 | ... AQ42: =SUM(AQ43:AQ47) -> 100
A43: Agriculture, Forestry & Fishing | B43: =Summary!B15/Summary!B$14*100 -> #DIV/0! | C43: =Summary!C15/Summary!C$14*100 -> #DIV/0! | D43: =Summary!D15/Summary!D$14*100 -> #DIV/0! | E43: =Summary!E15/Summary!E$14*100 -> #DIV/0! | F43: =Summary!F15/Summary!F$14*100 -> #DIV/0! | G43: =Summary!G15/Summary!G$14*100 -> #DIV/0! | H43: =Summary!H15/Summary!H$14*100 -> 28.104167 | I43: =Summary!I15/Summary!I$14*100 -> 27.532752 | ... AQ43: =Summary!AQ15/Summary!AQ$14*100 -> 22.61505
A44: Industry | B44: =Summary!B16/Summary!B$14*100 -> #DIV/0! | C44: =Summary!C16/Summary!C$14*100 -> #DIV/0! | D44: =Summary!D16/Summary!D$14*100 -> #DIV/0! | E44: =Summary!E16/Summary!E$14*100 -> #DIV/0! | F44: =Summary!F16/Summary!F$14*100 -> #DIV/0! | G44: =Summary!G16/Summary!G$14*100 -> #DIV/0! | H44: =Summary!H16/Summary!H$14*100 -> 25.035525 | I44: =Summary!I16/Summary!I$14*100 -> 24.763313 | ... AQ44: =Summary!AQ16/Summary!AQ$14*100 -> 26.268428
A45: Services | B45: =Summary!B17/Summary!B$14*100 -> #DIV/0! | C45: =Summary!C17/Summary!C$14*100 -> #DIV/0! | D45: =Summary!D17/Summary!D$14*100 -> #DIV/0! | E45: =Summary!E17/Summary!E$14*100 -> #DIV/0! | F45: =Summary!F17/Summary!F$14*100 -> #DIV/0! | G45: =Summary!G17/Summary!G$14*100 -> #DIV/0! | H45: =Summary!H17/Summary!H$14*100 -> 40.856966 | I45: =Summary!I17/Summary!I$14*100 -> 42.146389 | ... AQ45: =Summary!AQ17/Summary!AQ$14*100 -> 44.280548
...

Sheet Original_VA
A1: Table 3: ORIGINAL UNADJUSTED Value Added by activity at constant 2016/17 prices, BILLION SHILLINGS, 2016/17-2025/26
I2: 2008Q1 | J2: 2008Q2 | K2: 2008Q3 | L2: 2008Q4 | M2: 2009Q1 | N2: 2009Q2 | O2: 2009Q3 | P2: 2009Q4 | Q2: 2010Q1 | R2: 2010Q2 | S2: 2010Q3 | T2: 2010Q4 | U2: 2011Q1 | V2: 2011Q2 | W2: 2011Q3 | X2: 2011Q4 | Y2: 2012Q1 | Z2: 2012Q2 | AA2: 2012Q3 | AB2: 2012Q4 | AC2: 2013Q1 | AD2: 2013Q2 | AE2: 2013Q3 | AF2: 2013Q4 | AG2: 2014Q1 | AH2: 2014Q2 | AI2: 2014Q3 | AJ2: 2014Q4 | AK2: 2015Q1 | AL2: 2015Q2 | AM2: 2015Q3
A3: Year | I3: 2007/08 | K3: 2008/09 | O3: 2009/10 | S3: 2010/11 | W3: 2011/12 | AA3: 2012/13 | AC3: 2012/13 | AE3: 2013/14 | AF3: 2013/14 | AH3: 2013/14 | AI3: 2014/15 | AJ3: 2014/15 | AK3: 2014/15 | AM3: 2015/16 | AQ3: 2016/17 | AU3: 2017/18 | AY3: 2018/19 | BC3: 2019/20 | BG3: 2020/21 | BK3: 2021/22 | BO3: 2022/23 | BS3: 2023/24 | BW3: 2024/25 | CA3: 2025/26
A4: Period | B4: 2013/14 | C4: 2014/15 | D4: 2015/16 | E4: 2016/17 | F4: 2017/18 | I4: Q3 | J4: Q4 | K4: Q1 | L4: Q2 | M4: Q3 | N4: Q4 | O4: Q1 | P4: Q2 | Q4: Q3 | R4: Q4 | S4: Q1 | T4: Q2 | U4: Q3 | V4: Q4 | W4: Q1 | X4: Q2 | Y4: Q3 | Z4: Q4 | AA4: Q1 | AB4: Q2 | AC4: Q3 | AD4: Q4 | AE4: Q1 | AF4: Q2 | AG4: Q3 | AH4: Q4 | AI4: Q1 | AJ4: Q2 | AK4: Q3 | AL4: Q4 | AM4: Q1 | AN4: Q2 | AO4: Q3 | AP4: Q4 | AQ4: Q1 | AR4: Q2 | AS4: Q3 | AT4: Q4 | AU4: Q1 | AV4: Q2 | AW4: Q3 | AX4: Q4 | AY4: Q1 | AZ4: Q2 | BA4: Q3 | BB4: Q4 | BC4: Q1 | BD4: Q2 | BE4: Q3 | BF4: Q4 | BG4: Q1 | BH4: Q2 | BI4: Q3 | BJ4: Q4 | BK4: Q1 | BL4: Q2 | BM4: Q3 | BN4: Q4 | BO4: Q1 | BP4: Q2 | BQ4: Q3 | BR4: Q4 | BS4: Q1 | BT4: Q2 | BU4: Q3 | BV4: Q4 | BW4: Q1 | BX4: Q2 | BY4: Q3 | BZ4: Q4 | CA4: Q1 | CB4: Q2 | CC4: Q3
A5: GDP AT MARKET PRICES | B5: 95677.551 | C5: 101373.1 | D5: 105223.08 | E5: 108518.04 | F5: 115358.94 | H5: 0 | K5: 15766.403 | L5: 13927.632 | M5: 14022.629 | N5: 15998.234 | O5: 21078.882 | P5: 19122.748 | Q5: 19608.559 | R5: 20695.656 | S5: 23193.526 | T5: 21456.643 | U5: 21240.165 | V5: 21202.324 | W5: 24535.906 | X5: 21481.557 | Y5: 21447.288 | Z5: 22266.799 | AA5: 26058 | AB5: 22244.279 | AC5: 21603.992 | AD5: 21779.636 | AE5: 25541.078 | AF5: 22459.838 | AG5: 23000.644 | AH5: 24675.991 | AI5: 26399.959 | AJ5: 24996.444 | AK5: 24359.381 | AL5: 25617.315 | AM5: 28652.094 | AN5: 26475.799 | AO5: 24581.78 | AP5: 25513.407 | AQ5: 28577.247 | AR5: 26610.18 | AS5: 26240.178 | AT5: 27090.435 | AU5: 30772.237 | AV5: 28335.28 | AW5: 27653.331 | AX5: 28598.087 | AY5: 32487.642 | AZ5: 29958.631 | BA5: 29773.235 | BB5: 30567.095 | BC5: 34943.779 | BD5: 32466.458 | BE5: 30130.072 | BF5: 28870.102 | BG5: 34802.923 | BH5: 32477.008 | BI5: 30975.024 | BJ5: 32626.063 | BK5: 35622.436 | BL5: 34024.49 | BM5: 32716.662 | BN5: 34522.28 | BO5: 38746.737 | BP5: 35492.013 | BQ5: 33446.228 | BR5: 36506.452 | BS5: 41068.072 | BT5: 37544.31 | BU5: 35728.791 | BV5: 38581.884 | BW5: 43605.836 | BX5: 39557.991 | BY5: 38727.987 | BZ5: 40714.044 | CA5: 45718.884 | CB5: 42903.876 | CC5: 40970.227
A6: AGRICULTURE,FORESTRY&FISHING | B6: 23529.598 | C6: 24071.815 | D6: 24773.789 | E6: 25457.069 | F6: 26574.426 | K6: 6507.5645 | L6: 4895.3189 | M6: 4423.9452 | N6: 5495.5749 | O6: 6875.3793 | P6: 5088.8484 | Q6: 4451.0205 | R6: 5461.4456 | S6: 7007.5574 | T6: 5267.2451 | U6: 4769.982 | V6: 5440.697 | W6: 7871.5671 | X6: 5290.0544 | Y6: 4412.0205 | Z6: 5051.4272 | AA6: 8273.6224 | AB6: 5294.8849 | AC6: 4601.826 | AD6: 4760.2442 | AE6: 8300.5433 | AF6: 5337.7241 | AG6: 4567.2362 | AH6: 5324.0947 | AI6: 7787.9339 | AJ6: 5886.4232 | AK6: 4831.2409 | AL6: 5566.2174 | AM6: 7919.4675 | AN6: 5919.3821 | AO6: 5302.9236 | AP6: 5632.0158 | AQ6: 8012.3898 | AR6: 6110.5575 | AS6: 5359.3298 | AT6: 5974.7915 | AU6: 8783.7536 | AV6: 6199.5724 | AW6: 5495.0897 | AX6: 6096.0101 | AY6: 8974.6097 | AZ6: 6448.4413 | BA6: 5935.2774 | BB6: 6628.7289 | BC6: 9517.4185 | BD6: 6941.2508 | BE6: 5858.4835 | BF6: 7019.6669 | BG6: 10178.838 | BH6: 7480.0514 | BI6: 5874.7257 | BJ6: 7070.5839 | BK6: 10624.95 | BL6: 7330.892 | BM6: 6120.4467 | BN6: 7804.9868 | BO6: 11088.263 | BP6: 8197.4364 | BQ6: 6452.1008 | BR6: 7589.8403 | BS6: 11715.27 | BT6: 8365.8311 | BU6: 6712.9791 | BV6: 8392.5624 | BW6: 12457.04 | BX6: 9018.0558 | BY6: 7404.8569 | BZ6: 8683.3829 | CA6: 12839.64 | CB6: 9809.0589 | CC6: 7563.1391
A7: Cash crops | B7: 2077.9998 | C7: 2161.0304 | D7: 2332.5942 | E7: 2551.9497 | F7: 2702.9483 | K7: 399.61795 | L7: 634.82527 | M7: 662.45052 | N7: 513.9201 | O7: 405.66079 | P7: 538.9143 | Q7: 452.23425 | R7: 512.11823 | S7: 376.18328 | T7: 493.31842 | U7: 613.89027 | V7: 424.1042 | W7: 502.56926 | X7: 572.96078 | Y7: 573.37138 | Z7: 437.64169 | AA7: 455.48582 | AB7: 553.15128 | AC7: 634.25096 | AD7: 442.07724 | AE7: 509.03779 | AF7: 591.9906 | AG7: 581.34247 | AH7: 395.6289 | AI7: 502.58611 | AJ7: 538.13508 | AK7: 660.55567 | AL7: 459.75354 | AM7: 599.82266 | AN7: 607.24444 | AO7: 675.46962 | AP7: 450.05746 | AQ7: 503.80349 | AR7: 751.47235 | AS7: 756.6638 | AT7: 540.01006 | AU7: 711.49019 | AV7: 721.04285 | AW7: 772.20685 | AX7: 498.20843 | AY7: 708.23323 | AZ7: 768.35837 | BA7: 790.47225 | BB7: 563.82244 | BC7: 726.02296 | BD7: 837.1285 | BE7: 928.12524 | BF7: 560.87771 | BG7: 782.35957 | BH7: 933.39018 | BI7: 1033.3276 | BJ7: 683.9495 | BK7: 965.22972 | BL7: 980.0504 | BM7: 993.72889 | BN7: 688.45779 | BO7: 969.15812 | BP7: 928.29383 | BQ7: 1072.7337 | BR7: 681.86824 | BS7: 1030.9453 | BT7: 1070.8634 | BU7: 1245.7712 | BV7: 753.11773 | BW7: 1200.8309 | BX7: 1173.3745 | BY7: 1357.3298 | BZ7: 833.80664 | CA7: 1285.3573 | CB7: 1320.8624 | CC7: 1454.5946
A8: Food crops | B8: 12658.661 | C8: 12936.631 | D8: 13100.439 | E8: 13394.945 | F8: 14540.252 | K8: 4281.5106 | L8: 2451.0265 | M8: 2018.2066 | N8: 2897.7667 | O8: 4593.2382 | P8: 2657.0383 | Q8: 2072.3409 | R8: 2919.8031 | S8: 4627.9621 | T8: 2687.1305 | U8: 2145.4964 | V8: 3045.1339 | W8: 5002.0199 | X8: 2877.3534 | Y8: 1847.6599 | Z8: 2609.078 | AA8: 5742.9725 | AB8: 2416.9647 | AC8: 1728.4366 | AD8: 2411.7823 | AE8: 5602.7503 | AF8: 2407.5869 | AG8: 1852.7062 | AH8: 2795.6178 | AI8: 5040.2281 | AJ8: 3084.1246 | AK8: 1960.0486 | AL8: 2852.2293 | AM8: 5070.1412 | AN8: 3063.8262 | AO8: 2087.3268 | AP8: 2879.1445 | AQ8: 5158.2444 | AR8: 2956.6065 | AS8: 2216.3688 | AT8: 3063.7253 | AU8: 5764.4524 | AV8: 3189.0326 | AW8: 2406.5075 | AX8: 3180.2595 | AY8: 5806.2349 | AZ8: 3120.4628 | BA8: 2491.5732 | BB8: 3355.7462 | BC8: 6087.3682 | BD8: 3386.3637 | BE8: 2210.2087 | BF8: 3770.8716 | BG8: 6729.3932 | BH8: 3733.7504 | BI8: 2032.2914 | BJ8: 3595.1715 | BK8: 6847.8466 | BL8: 3553.494 | BM8: 2141.0816 | BN8: 4113.2181 | BO8: 7367.019 | BP8: 4243.1851 | BQ8: 2047.1733 | BR8: 3777.0373 | BS8: 7740.0659 | BT8: 4232.3299 | BU8: 2190.283 | BV8: 4166.6736 | BW8: 8152.8624 | BX8: 4529.7878 | BY8: 2262.5053 | BZ8: 4257.0001 | CA8: 8108.2689 | CB8: 4878.8645 | CC8: 2381.271
A9: Livestock | B9: 2922.9116 | C9: 3008.6418 | D9: 3092.2451 | E9: 3309.0902 | F9: 3544.9509 | K9: 645.89351 | L9: 642.39661 | M9: 648.87909 | N9: 652.65571 | O9: 651.96767 | P9: 659.3373 | Q9: 669.80162 | R9: 669.83864 | S9: 674.11805 | T9: 674.75889 | U9: 679.81969 | V9: 683.75147 | W9: 690.13315 | X9: 691.44572 | Y9: 696.56043 | Z9: 697.6197 | AA9: 694.1283 | AB9: 687.96788 | AC9: 732.72822 | AD9: 729.88094 | AE9: 730.74574 | AF9: 732.46069 | AG9: 729.28206 | AH9: 730.42308 | AI9: 744.36089 | AJ9: 748.7154 | AK9: 757.49263 | AL9: 758.07288 | AM9: 761.15519 | AN9: 764.50227 | AO9: 774.90151 | AP9: 791.68616 | AQ9: 803.94776 | AR9: 820.59322 | AS9: 836.92932 | AT9: 847.61996 | AU9: 869.7722 | AV9: 875.22137 | AW9: 895.75739 | AX9: 904.19998 | AY9: 927.06886 | AZ9: 942.41424 | BA9: 958.71971 | BB9: 977.13017 | BC9: 999.62611 | BD9: 1016.5699 | BE9: 1037.6779 | BF9: 1051.9475 | BG9: 1075.0903 | BH9: 1093.5814 | BI9: 1117.645 | BJ9: 1139.3805 | BK9: 1164.9148 | BL9: 1183.7106 | BM9: 1209.2184 | BN9: 1235.4276 | BO9: 1266.6927 | BP9: 1289.0045 | BQ9: 1324.7443 | BR9: 1336.3725 | BS9: 1364.9638 | BT9: 1392.5445 | BU9: 1421.1592 | BV9: 1449.5255 | BW9: 1480.2991 | BX9: 1512.2661 | BY9: 1550.6613 | BZ9: 1577.5316 | CA9: 1617.3459 | CB9: 1651.731 | CC9: 1652.4051
A10: Agriculture Support Services | B10: 14.143561 | C10: 16.636148 | D10: 15.869988 | E10: 16.47244 | F10: 16.412131 | K10: 5.2684781 | L10: 2.8887269 | M10: 1.7852487 | N10: 3.8214565 | O10: 5.2484117 | P10: 2.9083793 | Q10: 2.0130803 | R10: 4.3528051 | S10: 5.8403246 | T10: 3.0815591 | U10: 1.9768489 | V10: 4.08689 | W10: 5.029252 | X10: 2.5970925 | Y10: 1.6809127 | Z10: 3.7542687 | AA10: 5.2874578 | AB10: 2.8691069 | AC10: 1.8424318 | AD10: 4.0808902 | AE10: 5.2307922 | AF10: 2.7920344 | AG10: 1.8026609 | AH10: 4.3180733 | AI10: 6.2327006 | AJ10: 3.3809539 | AK10: 2.1372786 | AL10: 4.8852147 | AM10: 6.1750274 | AN10: 3.1636957 | AO10: 1.9526404 | AP10: 4.5786242 | AQ10: 6.2837288 | AR10: 3.325037 | AS10: 2.0494802 | AT10: 4.8141938 | AU10: 6.2956095 | AV10: 3.2755887 | AW10: 2.0080248 | AX10: 4.8329083 | AY10: 6.6083068 | AZ10: 3.5884171 | BA10: 2.1829168 | BB10: 5.4791027 | BC10: 7.7829336 | BD10: 4.3860543 | BE10: 2.1540787 | BF10: 4.6823231 | BG10: 7.2284747 | BH10: 3.9801091 | BI10: 2.7383126 | BJ10: 5.4484674 | BK10: 7.7592654 | BL10: 4.0780685 | BM10: 2.8418931 | BN10: 5.5823033 | BO10: 7.9640725 | BP10: 4.2517334 | BQ10: 2.8588657 | BR10: 5.6398941 | BS10: 8.3887802 | BT10: 4.5610538 | BU10: 3.0962641 | BV10: 6.1329907 | BW10: 8.7481039 | BX10: 4.4104034 | BY10: 3.0707098 | BZ10: 7.1536239 | CA10: 7.7163285 | CB10: 4.4194806 | CC10: 3.4144225
A11: Forestry | B11: 3631.3936 | C11: 3691.6987 | D11: 3867.0382 | E11: 4002.5745 | F11: 4137.4814 | K11: 631.38633 | L11: 576.26085 | M11: 580.94913 | N11: 878.106 | O11: 669.3003 | P11: 652.56728 | Q11: 696.29628 | R11: 795.52703 | S11: 787.43625 | T11: 831.64567 | U11: 762.18907 | V11: 732.9674 | W11: 1132.2042 | X11: 573.45764 | Y11: 700.34208 | Z11: 749.36263 | AA11: 803.07265 | AB11: 1025.0054 | AC11: 913.51194 | AD11: 766.19949 | AE11: 893.25768 | AF11: 1027.2584 | AG11: 837.4163 | AH11: 873.46123 | AI11: 948.52483 | AJ11: 918.5284 | AK11: 898.18312 | AL11: 926.46239 | AM11: 895.31852 | AN11: 883.22271 | AO11: 1159.6556 | AP11: 928.84137 | AQ11: 977.93029 | AR11: 992.65352 | AS11: 1004.7215 | AT11: 1027.2691 | AU11: 1007.3811 | AV11: 1003.7501 | AW11: 1044.0648 | AX11: 1082.2855 | AY11: 1044.1093 | AZ11: 1056.6287 | BA11: 1070.8268 | BB11: 1114.9791 | BC11: 1086.4176 | BD11: 1108.061 | BE11: 1120.3878 | BF11: 1111.3554 | BG11: 1056.878 | BH11: 1149.2585 | BI11: 1181.6024 | BJ11: 1168.9939 | BK11: 1107.6165 | BL11: 1115.7609 | BM11: 1243.7005 | BN11: 1233.5857 | BO11: 1152.8066 | BP11: 1158.8936 | BQ11: 1275.3325 | BR11: 1260.9317 | BS11: 1214.7921 | BT11: 1190.4314 | BU11: 1200.1467 | BV11: 1391.5844 | BW11: 1260.4901 | BX11: 1251.7752 | BY11: 1287.4128 | BZ11: 1362.3897 | CA11: 1383.2163 | CB11: 1355.0945 | CC11: 1225.0529
A12: Fishing | B12: 2224.4887 | C12: 2257.1777 | D12: 2365.6027 | E12: 2182.0367 | F12: 1632.3812 | K12: 543.8877 | L12: 587.92095 | M12: 511.67464 | N12: 549.30497 | O12: 549.96395 | P12: 578.0828 | Q12: 558.33437 | R12: 559.80578 | S12: 536.01737 | T12: 577.31004 | U12: 566.60978 | V12: 550.65321 | W12: 539.6114 | X12: 572.23982 | Y12: 592.40581 | Z12: 553.97091 | AA12: 572.67563 | AB12: 608.92647 | AC12: 591.05594 | AD12: 406.22338 | AE12: 559.52102 | AF12: 575.6355 | AG12: 564.68656 | AH12: 524.64564 | AI12: 546.0013 | AJ12: 593.53877 | AK12: 552.82358 | AL12: 564.81407 | AM12: 586.85491 | AN12: 597.42275 | AO12: 603.61733 | AP12: 577.70768 | AQ12: 562.18016 | AR12: 585.90691 | AS12: 542.59683 | AT12: 491.35281 | AU12: 424.36218 | AV12: 407.24998 | AW12: 374.54516 | AX12: 426.22385 | AY12: 482.35514 | AZ12: 556.98883 | BA12: 621.50255 | BB12: 611.57191 | BC12: 610.20066 | BD12: 588.74175 | BE12: 559.92985 | BF12: 519.93242 | BG12: 527.88856 | BH12: 566.09095 | BI12: 507.12106 | BJ12: 477.64002 | BK12: 531.58287 | BL12: 493.79799 | BM12: 529.87529 | BN12: 528.71517 | BO12: 324.62227 | BP12: 573.80759 | BQ12: 729.25809 | BR12: 527.99078 | BS12: 356.11407 | BT12: 475.10096 | BU12: 652.52279 | BV12: 625.52817 | BW12: 353.80898 | BX12: 546.44166 | BY12: 943.87711 | BZ12: 645.50127 | CA12: 437.73547 | CB12: 598.08703 | CC12: 846.40108
